Workbook
Name _____COX2: '[1]Determine K factor'!$B$7
Name _____NIT2: '[1]Determine K factor'!$B$9
Name _____OX2: '[1]Determine K factor'!$B$6
Name __COX2: '[2]Determine K factor'!$B$7
Name __NIT2: '[2]Determine K factor'!$B$9
Name __OX2: '[2]Determine K factor'!$B$6
Name Aa01_: '피토관,노즐표'!$D$20:$D$25
Name Aa02_03_04: '피토관,노즐표'!$E$20:$E$26
Name Aa05_06: '피토관,노즐표'!$F$20:$F$26
Name Aa07_: '피토관,노즐표'!$G$20:$G$26
Name An: '[2]Test Results'!$F$20
Name As: '[2]Test Results'!$B$19
Name Bwo: '[2]Determine K factor'!$B$10
Name calc_tm: '[2]Test Results'!$B$17
Name calc_ts: '[2]Test Results'!$B$13
Name COX: '[2]Determine K factor'!$B$8
Name Cp: '[2]Determine K factor'!$B$20
Name DH: '[2]Determine K factor'!$B$16
Name DHa: '[2]Determine K factor'!$B$15
Name Dn: '[2]Determine K factor'!$B$22
Name Dp: '[2]Determine K factor'!$B$14
Name Kf: '[2]Determine K factor'!$F$17
Name Md: '[2]Determine K factor'!$F$9
Name Ms: '[2]Determine K factor'!$F$10
Name Pb: '[2]Determine K factor'!$B$11
Name Pg: '[2]Determine K factor'!$B$12
Name Pm: '[2]Determine K factor'!$F$7
Name PM10_: '피토관,노즐표'!$J$20:$J$31
Name PM2.5_: '피토관,노즐표'!$K$20:$K$25
Name Ps: '[2]Determine K factor'!$F$5
Name Qa: '[2]Test Results'!$F$18
Name rel_tm: '[2]Determine K factor'!$B$18
Name rel_ts: '[2]Determine K factor'!$B$13
Name theta: '[2]Determine K factor'!$B$17
Name Tm: '[2]Determine K factor'!$F$8
Name Ts: '[2]Determine K factor'!$F$6
Name units: '[2]Determine K factor'!$F$23
Name Vlc: '[2]Test Results'!$B$10
Name Vm: '[2]Test Results'!$B$21
Name Vmstd: '[2]Test Results'!$F$9
Name Vr: '[2]Determine K factor'!$B$19
Name vs: '[2]Test Results'!$F$17
Name Yd: '[2]Determine K factor'!$B$21
Name 가스상시간: '한종_시료채취기록지 '!$E$34:$H$44
Name 가스상항목: '한종_시료채취기록지 '!$A$34:$A$44
Name 가스상항목시간: '한종_시료채취기록지 '!$A$34:$H$44
Name 기기번호: '피토관,노즐표'!$X$5:$X$11
Name 기술인력들: '피토관,노즐표'!$R$20:$R$32
Name 노즐목록: '피토관,노즐표'!$B$20:$B$27
Name 누출검사: '한종_시료채취기록지 '!$AG$15:$AG$16
Name 누출검사: '한종_시료채취기록지 (사용X)'!$Z$14:$Z$15
Name 누출검사단위: '한종_시료채취기록지 '!$AG$11:$AG$12
Name 누출검사단위: '한종_시료채취기록지 (사용X)'!$Z$10:$Z$11
Name 단위: '대기측정 분석결과서'!$AH$23:$AH$72
Name 먼지_중금속: '피토관,노즐표'!$AB$7:$AB$10
Name 미세먼지: '피토관,노즐표'!$AG$7:$AG$8
Name 수은_1: '피토관,노즐표'!$H$20:$H$26
Name 수은_2: '피토관,노즐표'!$I$20:$I$26
Name 수은1팀: '피토관,노즐표'!$AC$7
Name 수은2팀: '피토관,노즐표'!$AD$7

Sheet 포화수증기압 표 
A1: 온도[℃] | B1: 포화수증기압[㎜Hg]
A2: 0 | B2: 4.585 | E2: 배가스의
A3: 1 | B3: 4.929 | D3: 온도[℃] | E3: 포화수증기압[㎜Hg]
A4: 2 | B4: 5.295 | D4: ='먼지측정 사전 Data'!R69 -> #DIV/0! | E4: =LOOKUP(D4,A2:A102,B2:B102) -> #DIV/0!
A5: 3 | B5: 5.686
A6: 4 | B6: 6.102
A7: 5 | B7: 6.545
A8: 6 | B8: 7.016
A9: 7 | B9: 7.516
A10: 8 | B10: 8.048
A11: 9 | B11: 8.613
A12: 10 | B12: 9.212
A13: 11 | B13: 9.848
A14: 12 | B14: 10.52
A15: 13 | B15: 11.24
A16: 14 | B16: 11.99
... A102: 100 | B102: 760.7

Sheet Nozzle,K Factor
A1: Nozzle Size | AF1: K-Factor
J5: 0.0358 | M5: X | N5: =Y36 -> 5.184 | R5: X | S5: =J33 -> 0 | X5: =Y34+460 -> #DIV/0! | AA5: X | AB5: =J30 -> 8.03989e-05 | AE5: KF= | AH5: KstdCp2(ΔH@) | AN5: (Tm+Tconversion) | AU5: X | AV5: Ps | AX5: X | AY5: Md | BA5: (1-Bwo)2X | BE5: (Dn)4
A6: =SQRT(((J5*N5*S5)/(J7*N7*S7))*SQRT((X5*AB5)/(X7*AB7))) -> #DIV/0! | E6: = | V6: X | AN6: (Ts+Tconversion) | AV6: Pb | AY6: Ms
J7: =Y20+460 -> #DIV/0! | M7: X | N7: 0.84 | R7: X | S7: =1-J37 -> #DIV/0! | X7: =Y31 -> -0.0086879384 | AA7: X | AB7: =SQRT(J32) -> 2.236068
AF8: KF= | AH8: =((AH10*AK10*AM10)*((AQ10+273)/(AQ11+273))*(AV10/AV11)*(AY10/AY11)*BA10*BE10) -> #DIV/0!
B10: Nozzle Size(구형) | R10: Nozzle Size(신형) | AH10: =J30 -> 8.03989e-05 | AK10: =('먼지측정 사전 Data'!H65)^2 -> 0 | AM10: ='먼지측정 사전 Data'!H63 -> 0 | AP10: ( | AQ10: =J20 -> #DIV/0! | AS10: +273) | AU10: X | AV10: =J27 -> #DIV/0! | AX10: X | AY10: =J28 -> 28 | BA10: =(1-J37)^2 -> #DIV/0! | BD10: X | BE10: =I17^4 -> 24335.579
C11: inch | F11: cm | I11: mm | L11: cm2 | S11: inch | V11: cm | Y11: mm | AB11: cm2 | AP11: ( | AQ11: =J34 -> #DIV/0! | AS11: +273) | AV11: =J19 -> 0 | AY11: =J29 -> #DIV/0!
B12: 1. | C12: 0.12559 | F12: =C12*2.54 -> 0.3189986 | I12: =F12*10 -> 3.189986 | L12: =3.14*(F12/2)^2 -> 0.079881684 | R12: 1. | S12: 0.12402 | V12: =S12*2.54 -> 0.3150108 | Y12: =V12*10 -> 3.150108 | AB12: =3.14*(V12/2)^2 -> 0.077896966
B13: 2. | C13: 0.17677 | F13: =C13*2.54 -> 0.4489958 | I13: =F13*10 -> 4.489958 | L13: =3.14*(F13/2)^2 -> 0.15825382 | R13: 2. | S13: 0.17126 | V13: =S13*2.54 -> 0.4350004 | Y13: =V13*10 -> 4.350004 | AB13: =3.14*(V13/2)^2 -> 0.1485419
B14: 3. | C14: 0.24645 | F14: =C14*2.54 -> 0.625983 | I14: =F14*10 -> 6.25983 | L14: =3.14*(F14/2)^2 -> 0.30760595 | R14: 3. | S14: 0.24213 | V14: =S14*2.54 -> 0.6150102 | Y14: =V14*10 -> 6.150102 | AB14: =3.14*(V14/2)^2 -> 0.29691647
B15: 4. | C15: 0.30354 | F15: =C15*2.54 -> 0.7709916 | I15: =F15*10 -> 7.709916 | L15: =3.14*(F15/2)^2 -> 0.46662602 | R15: 4. | S15: 0.29724 | V15: =S15*2.54 -> 0.7549896 | Y15: =V15*10 -> 7.549896 | AB15: =3.14*(V15/2)^2 -> 0.4474573
B16: 5. | C16: 0.37086 | F16: =C16*2.54 -> 0.9419844 | I16: =F16*10 -> 9.419844 | L16: =3.14*(F16/2)^2 -> 0.69655767 | R16: 5. | S16: 0.36024 | V16: =S16*2.54 -> 0.9150096 | Y16: =V16*10 -> 9.150096 | AB16: =3.14*(V16/2)^2 -> 0.65723542
B17: 6. | C17: 0.49173 | F17: =C17*2.54 -> 1.2489942 | I17: =F17*10 -> 12.489942 | L17: =3.14*(F17/2)^2 -> 1.2245894 | R17: 6. | S17: 0.42717 | V17: =S17*2.54 -> 1.0850118 | Y17: =V17*10 -> 10.850118 | AB17: =3.14*(V17/2)^2 -> 0.92414173
R18: 7. | S18: 0.49015 | V18: =S18*2.54 -> 1.244981 | Y18: =V18*10 -> 12.44981 | AB18: =3.14*(V18/2)^2 -> 1.2167325
A19: 1. | B19: 대기압 | I19: : | J19: ='먼지측정 사전 Data'!H20 -> 0 | O19: mmHg | Y19: =J19/25.4 -> 0 | AC19: inchHg
A20: 2. | B20: 가스메타온도™ | I20: : | J20: ='먼지측정 사전 Data'!R74 -> #DIV/0! | O20: ℃ | Y20: =((9/5)*J20)+32 -> #DIV/0! | AC20: ℉
A21: 3. | B21: 동압 | I21: : | J21: 2 | O21: mmH2O
A22: 4. | B22: 정압 | I22: : | J22: ='먼지측정 사전 Data'!R71 -> #DIV/0! | O22: mmH2O
A23: 5. | B23: O2% | I23: : | J23: ='먼지측정 사전 Data'!H14 -> 0 | O23: %
A24: 6. | B24: CO2% | I24: : | J24: ='먼지측정 사전 Data'!H16 -> 0 | O24: %
A25: 7. | B25: CO% | I25: : | J25: ='먼지측정 사전 Data'!H17 -> 0
A26: 8. | B26: N2% | I26: : | J26: ='먼지측정 사전 Data'!H19 -> 100 | O26: %
A27: 9. | B27: Absolute Stack Pressure(Ps) | I27: : | J27: =('먼지측정 사전 Data'!H20)+('먼지측정 사전 Data'!R71/13.6) -> #DIV/0! | O27: mmHg
A28: 10. | B28: Md | I28: : | J28: =((0.32*J23)+(0.44*J24)+(0.28*J26)+(0.28*J25)) -> 28
A29: 11. | B29: Ms | I29: : | J29: =(J28*(1-J37))+(J37*18.01) -> #DIV/0!
A30: 12. | B30: Kstd | I30: : | J30: =8.03989*10^-5 -> 8.03989e-05
A31: 13. | B31: G.A.P(Ps) | I31: : | J31: -3 | O31: mmH2O | Y31: =Y19+(J31*(760/10332)*(1/25.4)) -> -0.0086879384 | AC31: inchHg
A32: 14. | B32: 동압(Δp) | I32: : | J32: 5 | O32: mmH2O | Y32: =J32*((760/10332)*(1/25.4)) -> 0.014479897 | AC32: inchHg
A33: 15. | B33: A.M.P(Pm) | I33: : | J33: =Y19 -> 0 | O33: inchHg
A34: 16. | B34: 배가스온도(Ts) | I34: : | J34: ='먼지측정 사전 Data'!R69 -> #DIV/0! | O34: ℃ | Y34: =((9/5)*J34)+32 -> #DIV/0! | AC34: ℉
A35: 17. | B35: 오리피스차압ΔH | I35: : | J35: 22.854 | O35: mmH2O | Y35: =J35*((760/10332)*(1/25.4)) -> 0.066184715 | AC35: inchHg
A36: 18. | B36: 포집유량(Qm) | I36: : | J36: 3 | O36: Ft3 | Y36: =J36*1.728 -> 5.184 | AC36: inch3
A37: 19. | B37: 수분량(Bws) | I37: : | J37: =('먼지측정 사전 Data'!H59)/100 -> #DIV/0!
A38: 20. | B38: P's.t.v.An | I38: :
A39: 21. | I39: :
A40: 22. | I40: :
A41: 23. | I41: :
A42: 24. | I42: :
A43: 25. | I43: :

Sheet 먼지측정 사전 Data
A1: Lee ISO% Program
A3: 0. 사전정보
A4: 채 취 자 (팀) | G4: : | N4: 접수번호:
A5: 시료분석기간 | G5: : | H5: =TEXT(N6,"yyyy-mm-dd")&" ~ "&TEXT(R5,"yyyy-mm-dd") -> 2026-02-06 ~ 1900-01-00 | M5: 채취일 | O5: =N5 -> 0 | P5: 0 | Q5: 분석완료일 | S5: =R5 -> 0
A6: 총 채취시간 | G6: : | J6: ~ | M6: 접수일 | N6: 46059 | Q6: 성적서발행일 | R6: 46066 | S6: =R6 -> 46066
A7: 기 후 조 건 | G7: : | H7: 대기압(Hpa) | J7: 기상 | L7: 기온(℃) | N7: 습도(%) | O7: 풍향(풍) | P7: 풍속(m/s)
H9: 대기압(mmHg) | M9: =ROUND(H8*760/1013.25,1) -> 0
A11: 1.연소가스 분석기 Parts.
A13: O2(산소측정값) | G13: : | M13: % | O13: 표준산소(%) | R13: 20.9 | T13: 산소보정항목 없을 시 20.9 기입해주세요 20.9 안 할 시 적힌 숫자대로 유량이 보정되어버립니다
H14: =ROUND((H13+J13+L13)/3,1) -> 0
A15: CO2(이산화탄소) | G15: : | M15: % | O15: 산소보정계수 | R15: =IF(R13=20.9,"-",(21-R13)/(21-H14)) -> -
H16: =ROUND((H15+J15+L15)/3,1) -> 0
A17: CO(일산화탄소) | G17: : | M17: % | O17: 배가스밀도(ro) | R17: =ROUND(((32*H14+44*H16+28*H19)*(100-H59)/100+(18*H59))/(22.4*100),2) -> #DIV/0!
H18: =ROUND((H17+J17+L17)/3,1) -> 0
A19: N2(질소) | G19: : | H19: =100-(H14+H16+H17) -> 100 | M19: % | T19: -> | U19: 32 | V19: * | W19: =H14 -> 0 | X19: + | Y19: 44 | Z19: * | AA19: =H16 -> 0 | AB19: + | AC19: 28 | AD19: * | AE19: =H19 -> 100 | AF19: * | AG19: 100 | AH19: - | AI19: =H59 -> #DIV/0! | AJ19: / | AK19: 100 | AL19: + | AM19: 18 | AN19: * | AO19: =H59 -> #DIV/0!
A20: 측정공의대기압 | G20: : | H20: =M9 -> 0 | M20: mmHg | Y20: 22.4 | Z20: * | AA20: 100
F21: NOx | M21: =ROUND((H21+J21+L21)/3,1) -> 0 | O21: ro 는 1~1.3 이면 적당
A22: 2.측정점 산정 Parts. | F22: SOx | M22: =ROUND((H22+J22+L22)/3,1) -> 0 | O22: CO | V22: =ROUND((Q22+S22+U22)/3,1) -> 0
A24: 굴뚝직경 (2R)(m) | D24: 반경 구분수 | F24: 측정점 수 | I24: 굴뚝중심에서 측정점까지의 거리(m)
I25: r1 | K25: r2 | M25: r3 | O25: r4 | Q25: r5
A26: 1이하 | D26: 1 | F26: 4 | I26: 0.707 | K26: - | M26: - | O26: - | Q26: -
A27: 1초과 2이하 | D27: 2 | F27: 8 | I27: 0.5 | K27: 0.866 | M27: - | O27: - | Q27: -
A28: 2초과 4이하 | D28: 3 | F28: 12 | I28: 0.408 | K28: 0.707 | M28: 0.913 | O28: - | Q28: -
A29: 4초과 4.5이하 | D29: 4 | F29: 16 | I29: 0.354 | K29: 0.612 | M29: 0.791 | O29: 0.935 | Q29: -
A30: 4.5초과 | D30: 5 | F30: 20 | I30: 0.316 | K30: 0.548 | M30: 0.707 | O30: 0.837 | Q30: 0.949
A31: 연도직경(m)원형 | F31: 연도 단면적(m2) | K31: =IF(D31>0,ROUND(PI()*D31*D31/4,3),ROUND(D33*E33,3)) -> 0 | M31: 플랜지 길이(m) | Q31: 0 | S31: 최종직경 | U31: =D31 -> 0
A33: 연도직경(m)사각형 가로x세로 | F33: 수평유무(0,1) | J33: 0
A35: ▣ 플렌지 끝에서 굴뚝 안쪽으로 Probe삽입길이 ▣ | M35: 측정점: | N35: =COUNT(D39:N44) -> 1
A37: 굴뚝직경 (2R)(m) | D37: r1 | F37: r2 | I37: r3 | K37: r4 | M37: r5
A39: 0.564(A=0.250)이하 | D39: =IF(D31>0.564,"",(D31/2)+Q31) -> 0 | F39: - | I39: - | K39: - | M39: -
A40: 1이하 | D40: =IF(AND(U31<=1,U31>0.564),((D31/2-(D31/2)*I26)+Q31),"") | F40: - | I40: - | K40: - | M40: -
A41: 1초과 2이하 | D41: =IF(AND(U31>1,U31<=2),((D31/2-(D31/2)*I27)+Q31),"") | F41: =IF(AND(U31>1,U31<=2),((D31/2-(D31/2)*K27)+Q31),"") | I41: - | K41: - | M41: -
A42: 2초과 4이하 | D42: =IF(AND(U31>2,U31<=4),((D31/2-(D31/2)*I28)+Q31),"") | F42: =IF(AND(U31>2,U31<=4),((D31/2-(D31/2)*K28)+Q31),"") | I42: =IF(AND(U31>2,U31<=4),((D31/2-(D31/2)*M28)+Q31),"") | K42: - | M42: -
A43: 4초과 4.5이하 | D43: =IF(AND(U31>4,U31<=4.5),(((D31/2)-(D31/2)*I29)+Q31),"") | F43: =IF(AND(U31>4,U31<=4.5),(((D31/2)-(D31/2)*K29)+Q31),"") | I43: =IF(AND(U31>4,U31<=4.5),(((D31/2)-(D31/2)*M29)+Q31),"") | K43: =IF(AND(U31>4,U31<=4.5),(((D31/2)-(D31/2)*O29)+Q31),"") | M43: -
A44: 4.5초과 | D44: =IF(U31<=4.5,"",(((D31/2)-(D31/2)*I30)+Q31)) | F44: =IF(U31<=4.5,"",(((D31/2)-(D31/2)*K30)+Q31)) | I44: =IF(U31<=4.5,"",(((D31/2)-(D31/2)*M30)+Q31)) | K44: =IF(U31<=4.5,"",(((D31/2)-(D31/2)*O30)+Q31)) | M44: =IF(U31<=4.5,"",(((D31/2)-(D31/2)*Q30)+Q31))
A46: 3.수분량 Parts.
A48: 측정전 흡수병1+2의 무게 | G48: : | M48: g
A49: 측정후 흡수병1+2의 무게 | G49: : | M49: g
A50: 흡수병전후무게(Ma) | G50: : | H50: =H49-H48 -> 0 | M50: g
A51: 가스메타입구온도 | G51: : | M51: ℃
...

Sheet 피토관,노즐표
B3: Aa01 | D3: Aa02 | F3: Aa03 | H3: Aa04 | J3: Aa05 | L3: Aa06 | N3: Aa07
B5: 44.0411 | D5: 47.2923 | F5: 46.5 | H5: 47.4 | J5: 47.3 | L5: 46.3 | N5: 49.8 | P5: 수은1팀 | R5: 수은2팀 | T5: 수은3팀 | V5: 수은4팀 | X5: 44.0411 | Z5: 피토관구분
B6: 0 | C6: 0.813 | D6: 0 | E6: 0.825 | F6: 0 | G6: 0.817 | H6: 0 | I6: 0.807 | J6: 0 | K6: 0.818 | L6: 0 | M6: 0.826 | N6: 0 | O6: 0.821 | P6: 0 | Q6: 0.81 | R6: 0 | S6: 0.816 | T6: 0 | U6: 0.802 | V6: 0 | W6: 0.802 | X6: 47.2923 | Z6: 먼지_중금속 | AB6: 먼지_중금속 | AC6: 수은1팀 | AD6: 수은2팀 | AE6: 수은3팀 | AF6: 수은4팀 | AG6: 미세먼지
B7: 5.08 | C7: 0.832 | D7: 5.08 | E7: 0.828 | F7: 4.94 | G7: 0.822 | H7: 4.95 | I7: 0.829 | J7: 5.08 | K7: 0.825 | L7: 5.08 | M7: 0.83 | N7: 5.08 | O7: 0.835 | P7: 4.8 | Q7: 0.829 | R7: 4.96 | S7: 0.824 | T7: 4.8 | U7: 0.828 | V7: 4.8 | W7: 0.826 | X7: 46.5 | Z7: 수은1팀 | AB7: Aa01_ | AC7: 수은_1 | AD7: 수은_1 | AE7: 수은_1 | AF7: 수은_2 | AG7: PM10_
P8: 10.21 | Q8: 0.829 | R8: 10.41 | S8: 0.818 | T8: 10.2 | U8: 0.83 | V8: 10.2 | W8: 0.83 | X8: 47.4 | Z8: 수은2팀 | AB8: Aa02_03_04 | AG8: PM2.5_
P9: 15.48 | Q9: 0.83 | R9: 14.65 | S9: 0.822 | T9: 15.36 | U9: 0.833 | V9: 15.41 | W9: 0.836 | X9: 47.3 | Z9: 수은3팀 | AB9: Aa05_06
P10: 19.63 | Q10: 0.832 | R10: 19.9 | S10: 0.825 | T10: 19.43 | U10: 0.83 | V10: 19.46 | W10: 0.83 | X10: 46.3 | Z10: 수은4팀 | AB10: Aa07_
P11: 24.52 | Q11: 0.826 | R11: 25.13 | S11: 0.823 | T11: 24.45 | U11: 0.83 | V11: 24.44 | W11: 0.83 | X11: 49.8 | Z11: 미세먼지
P12: 29.84 | Q12: 0.834 | R12: 30.32 | S12: 0.825 | T12: 29.58 | U12: 0.831 | V12: 29.7 | W12: 0.828 | X12: 먼지_중금속
P13: 35.2 | Q13: 0.832 | R13: 34.61 | S13: 0.823 | T13: 35.02 | U13: 0.835 | V13: 35.01 | W13: 0.833 | X13: 수은1팀
P14: 38.72 | Q14: 0.836 | X14: 수은2팀
B15: ENK169 | D15: ENK394 | F15: ENK942 | H15: ENK946 | J15: ENK1297 | L15: ENK1510 | N15: ENK1464 | P15: ENK931 | R15: ENK807 | T15: ENK1214 | V15: ENK1214 | X15: 수은3팀
X16: 수은4팀
X17: 미세먼지
B18: 노즐목록 | V18: 미세먼지
D19: Aa01 | E19: Aa02,03,04 | F19: Aa05,06 | G19: Aa07 | H19: 수은_1 | I19: 수은_2 | J19: PM10 | K19: PM2.5 | O19: Yd계수표 | R19: 기술인력들 | V19: 0 | W19: 0.818
B20: Aa01_ | D20: 0.319 | E20: 0.315 | F20: 0.395 | G20: 0.39 | H20: 0.31 | I20: 0.41 | J20: 0.318 | K20: 0.318 | M20: 풍향목록 | O20: 44.0411 | P20: 1.0035 | R20: 박 민 우 | V20: 4.97 | W20: 0.816
B21: Aa02_03_04 | D21: 0.449 | E21: 0.435 | F21: 0.545 | G21: 0.53 | H21: 0.455 | I21: 0.545 | J21: 0.345 | K21: 0.345 | M21: 정온(실내) | O21: 47.2923 | P21: 1.0044 | R21: 맹 호 수 | V21: 10.32 | W21: 0.824
B22: Aa05_06 | D22: 0.626 | E22: 0.615 | F22: 0.625 | G22: 0.62 | H22: 0.625 | I22: 0.655 | J22: 0.381 | K22: 0.381 | M22: 정온 | O22: 46.5 | P22: 1 | R22: 이 동 협 | V22: 14.66 | W22: 0.821
B23: Aa07_ | D23: 0.771 | E23: 0.755 | F23: 0.695 | G23: 0.71 | H23: 0.765 | I23: 0.754 | J23: 0.417 | K23: 0.417 | M23: 동 | O23: 47.4 | P23: 1 | R23: 정 우 창 | V23: 19.8 | W23: 0.822
B24: 수은_1 | D24: 0.942 | E24: 0.915 | F24: 0.775 | G24: 0.78 | H24: 0.93 | I24: 0.85 | J24: 0.457 | K24: 0.457 | M24: 서 | O24: 47.3 | P24: 1 | R24: 신 민 석 | V24: 25.07 | W24: 0.825
B25: 수은_2 | D25: 1.249 | E25: 1.085 | F25: 0.935 | G25: 0.94 | H25: 1.085 | I25: 0.95 | J25: 0.5 | K25: 0.5 | M25: 남 | O25: 46.3 | P25: 1 | R25: 강 민 수 | V25: 30.2 | W25: 0.827
B26: PM10_ | E26: 1.245 | F26: 1.275 | G26: 1.26 | H26: 1.265 | I26: 1.235 | J26: 0.546 | K26: 공정시험법상 큰노즐 사용불가 | M26: 북 | O26: 49.8 | P26: 1 | R26: 정 종 원 | V26: 34.59 | W26: 0.83
B27: PM2.5_ | J27: 0.592 | M27: 남동 | R27: 김 흥 록
J28: 0.671 | M28: 남서 | R28: 강 원 석 | V28: AS690
J29: 0.762 | M29: 북동 | R29: 송 정 현
J30: 0.869 | M30: 북서
J31: 0.991 | M31: 남남동 | R31: 김 인 현
M32: 동남동 | R32: 김 태 우
M33: 남남서
M34: 서남서
M35: 북북동
B36: 여분 피토관 | M36: 동북동
G37: 기기별 누출검사 진공게이지 단위 | M37: 북북서
B38: 0 | C38: 0.815 | D38: 0 | E38: 0.814 | G38: 44.0411 | H38: 15 inchHg | M38: 서북서
B39: 4.94 | C39: 0.826 | D39: 4.95 | E39: 0.814 | G39: 47.2923 | H39: 15 inchHg
B40: 10.4 | C40: 0.826 | D40: 10.39 | E40: 0.82 | G40: 46.5 | H40: 381 mmHg
B41: 14.62 | C41: 0.826 | D41: 14.67 | E41: 0.819 | G41: 47.4 | H41: 381 mmHg
B42: 19.87 | C42: 0.825 | D42: 19.89 | E42: 0.818 | G42: 47.3 | H42: 15 inchHg
B43: 25.03 | C43: 0.83 | D43: 25.03 | E43: 0.819 | G43: 46.3 | H43: 15 inchHg
...

Sheet 대기측정 분석결과서
A1: 시료 채취 | D1: =IF(COUNT('먼지측정 사전 Data'!H72)=0,"",'먼지측정 사전 Data'!A95) | H1: 대기측정 분석 결과서 | W1: 시료 채취 | Z1: ='먼지측정 사전 Data'!N5 -> 0
A2: 여지 번호 | W2: 일 시
A3: 배 출 업 소 | P3: 측 정 대 행 업 소
A4: 업 소 명 | P4: 업 소 명 | U4: 한국종합환경산업㈜
A5: 소 재 지 | P5: 소 재 지 | U5: 부산광역시 강서구 대저중앙로394번가길 56(대저1동) | AG5: 맑음
A6: 대 표 자 | I6: 업종 | P6: 대 표 자 | U6: 김항재 | AG6: 흐림
A7: 배출 시설 | E7: 여 형 석 | J7: 시료 채취 | L7: 윤 명 원 | P7: 시 료 채 취 자 | U7: ='먼지측정 사전 Data'!H4 -> 0 | X7: ='먼지측정 사전 Data'!K4 -> 0 | AG7: 비
A8: 관 리 인 | J8: 입 회 자 | P8: 시 료 분 석 기 간 | U8: ='먼지측정 사전 Data'!H5 -> 2026-02-06 ~ 1900-01-00 | AG8: 눈
A9: 시 설 별 | I9: 주생산 품목 | L9: 자동차 | P9: 시 료 분 석 | U9: 이 나 영
A10: 사업장 종별 | G10: 종 | H10: 측정공 높이 | I10: 방지시설용량 | P10: 검 사 자
A11: 배출구 종별 | G11: 종 | I11: 연료 및 사용량 | L11: - | N11: Kg/Hr | P11: 발생원의 종 류 | U11: =TRIM(_xlfn.TEXTJOIN(" ", TRUE, IF(TYPE(F23)=1, C23, ""), IF(TYPE(F24)=1, C24, ""), IF(TYPE(F25)=1, C25, ""), IF(TYPE(F26)=1, C26, ""), IF(TYPE(F27)=1, C27, ""), IF(TYPE(F28)=1, C28, ""), IF(TYPE(F29)=1, C29, ""), IF(TYPE(F30)=1, C30, ""), IF(TYPE(F31)=1, C31, ""), IF(TYPE(F32)=1, C32, ""), IF(TYPE(F33)=1, C33, ""), IF(TYPE(F34)=1, C34, ""), IF(TYPE(F35)=1, C35, ""), IF(TYPE(F36)=1, C36, ""), IF(TYPE(F37)=1, C37, ""), IF(TYPE(F38)=1, C38, ""), IF(TYPE(F39)=1, C39, ""), IF(TYPE(F40)=1, C40, ""), IF(TYPE(F41)=1, C41, ""), IF(TYPE(F42)=1, C42, ""), IF(TYPE(F43)=1, C43, ""), IF(TYPE(F44)=1, C44, ""), IF(TYPE(F45)=1, C45, ""), IF(TYPE(F46)=1, C46, ""), IF(TYPE(F47)=1, C47, ""), IF(TYPE(F48)=1, C48, ""), IF(TYPE(F49)=1, C49, ""), IF(TYPE(F50)=1, C50, ""), IF(TYPE(F51)=1, C51, ""), IF(TYPE(F52)=1, C52, ""), IF(TYPE(F53)=1, C53, ""), IF(TYPE(F54)=1, C54, ""), IF(TYPE(F55)=1, C55, ""), IF(TYPE(F56)=1, C56, ""), IF(TYPE(F57)=1, C57, ""), IF(TYPE(F58)=1, C58, ""), IF(TYPE(F59)=1, C59, ""), IF(TYPE(F60)=1, C60, ""), IF(TYPE(F61)=1, C61, ""), IF(TYPE(F62)=1, C62, ""), IF(TYPE(F63)=1, C63, ""), IF(TYPE(F64)=1, C64, ""), IF(TYPE(F65)=1, C65, ""), IF(TYPE(F66)=1, C66, ""), IF(TYPE(F67)=1, C67, ""), IF(TYPE(F68)=1, C68, ""), IF(TYPE(F69)=1, C69, ""), IF(TYPE(F70)=1, C70, ""), IF(TYPE(F71)=1, C71, ""), IF(TYPE(F72)=1, C72, ""), IF(TYPE(F73)=1, C73, ""), IF(TYPE(F74)=1, C74, "") )) & " (총 " & COUNTIF(AL23:AL74, 1) & " 항목)" -> THC (총 1 항목) | AM11: ※ppm= (mg/m3) * (22.4/mw)
A12: 배출시설 종류
A13: 방지시설 종류 | AG13: 분석완료일
A14: 1. 연도조건 및 기후조건
A15: 연도모양 | E15: 기 상 | I15: 기 온 | M15: 습 도 | Q15: 기 압 | V15: 풍 향 | AA15: 풍 속
A17: =IF('먼지측정 사전 Data'!D31>0,"원형","사각형") -> 사각형 | E17: ='먼지측정 사전 Data'!J8 -> 0 | I17: ='먼지측정 사전 Data'!L8 -> 0 | L17: ℃ | M17: ='먼지측정 사전 Data'!N8 -> 0 | P17: % | Q17: ='먼지측정 사전 Data'!H20 -> 0 | T17: mmHg | V17: ='먼지측정 사전 Data'!O8 -> 0 | Y17: 풍 | AA17: ='먼지측정 사전 Data'!P8 -> 0 | AD17: m/s
AG19: 산소보정계수
A20: 2. 결과 및 공정시험법 | AG20: =(21-'먼지측정 사전 Data'!R13)/(21-'먼지측정 사전 Data'!H14) -> 0.0047619048
A21: 측정항목 | F21: 결과치 | M21: 기기 | V21: 공정시험법
F22: 결과값 | G22: 실험결과 | J22: O2보정 | AG22: 방법검출한계 | AH22: 단위 | AI22: 소수점표기값 | AO22: 현대차 요구 항목명
C23: =IF(ISNUMBER(SEARCH("현대자동차",$E$4)),AO23,AJ23) -> 먼지 | F23: =IF(G23="","",J23*G23) | G23: =IF('먼지측정 사전 Data'!J94=0,"",'먼지측정 사전 Data'!J94) | J23: 1 | M23: 반자동식 측정법/원통여지법 | Z23: ES 01301.1e | AG23: 1e-08 | AH23: mg/S㎥ | AI23: 1 | AJ23: 먼지 | AL23: =TYPE(F23) -> 2 | AO23: 먼지
C24: =IF(ISNUMBER(SEARCH("현대자동차",$E$4)),AO24,AJ24) -> 매연 | F24: =IF(G24="","",G24) | J24: 1 | M24: 링겔만비탁표 | Z24: ES 01313.1b | AG24: -1 | AH24: 도 이하 | AI24: 0 | AJ24: 매연 | AL24: =TYPE(F24) -> 2 | AO24: 매연
C25: =IF(ISNUMBER(SEARCH("현대자동차",$E$4)),AO25,AJ25) -> NOx | F25: =IF(G25="","",AVERAGE(G25:I25)) | G25: =IF('먼지측정 사전 Data'!H21="","",'먼지측정 사전 Data'!H21) | H25: =IF('먼지측정 사전 Data'!J21="","",'먼지측정 사전 Data'!J21) | I25: =IF('먼지측정 사전 Data'!L21="","",'먼지측정 사전 Data'!L21) | M25: 자동측정법/자동연속장치 | Z25: ES 01308.1b | AG25: 1e-06 | AH25: ppm | AI25: 1 | AJ25: NOx | AL25: =TYPE(F25) -> 2 | AO25: 질소산화물
C26: =IF(ISNUMBER(SEARCH("현대자동차",$E$4)),AO26,AJ26) -> SOx | F26: =IF(G26="","",AVERAGE(G26:I26)) | G26: =IF('먼지측정 사전 Data'!H22="","",'먼지측정 사전 Data'!H22) | H26: =IF('먼지측정 사전 Data'!J22="","",'먼지측정 사전 Data'!J22) | I26: =IF('먼지측정 사전 Data'!L22="","",'먼지측정 사전 Data'!L22) | M26: 자동측정법/자동연속장치 | Z26: ES 01307.1b | AG26: 1e-07 | AH26: ppm | AI26: 1 | AJ26: SOx | AL26: =TYPE(F26) -> 2 | AO26: 황산화물
C27: =IF(ISNUMBER(SEARCH("현대자동차",$E$4)),AO27,AJ27) -> CO | F27: =IF(G27="","",AVERAGE(G27:I27)) | G27: =IF('먼지측정 사전 Data'!Q22="","",'먼지측정 사전 Data'!Q22) | H27: =IF('먼지측정 사전 Data'!S22="","",'먼지측정 사전 Data'!S22) | I27: =IF('먼지측정 사전 Data'!U22="","",'먼지측정 사전 Data'!U22) | M27: 전기화학식(정전위전해법)/자동연속장치 | Z27: ES 01304.2c | AG27: 1e-06 | AH27: ppm | AI27: 1 | AJ27: CO | AL27: =TYPE(F27) -> 2 | AO27: 일산화탄소
C28: =IF(ISNUMBER(SEARCH("현대자동차",$E$4)),AO28,AJ28) -> THC | J28: 1 | M28: 불꽃이온화검출기법 | Z28: ES 01507.1d | AG28: 1e-06 | AH28: ppm | AI28: 1 | AJ28: THC | AL28: =TYPE(F28) -> 1 | AO28: 탄화수소(THC)
C29: 미세먼지(PM-10) | F29: =IF(G29="","",J29*G29) | J29: 1 | M29: 반자동식 측정법 | Z29: ES 01317.1b | AG29: 0 | AH29: mg/S㎥ | AI29: 1 | AJ29: 미세먼지(PM-10) | AL29: =TYPE(F29) -> 2 | AO29: 미세먼지(PM-10)
C30: 미세먼지(PM-2.5) | F30: =IF(G30="","",J30*G30) | J30: 1 | M30: 반자동식 측정법 | Z30: ES 01317.1b | AG30: 0 | AH30: mg/S㎥ | AI30: 1 | AJ30: 미세먼지(PM-2.5) | AL30: =TYPE(F30) -> 2
F31: =IF(G31="","",J31*G31)
C32: =IF(ISNUMBER(SEARCH("현대자동차",$E$4)),AO32,AJ32) -> 암모니아 | F32: =IF(H32="-","",IF(H32="ND",0,(IF(H32="","",J32*H32)))) | J32: 1 | M32: 자외선/가시선분광법-인도페놀법 | Z32: ES 01303.1d | AG32: 0.4 | AH32: ppm | AI32: 1 | AJ32: 암모니아 | AL32: =TYPE(F32) -> 2 | AO32: 암모니아
C33: =IF(ISNUMBER(SEARCH("현대자동차",$E$4)),AO33,AJ33) -> 염화수소 | F33: =IF(H33="-","",IF(H33="ND",0,(IF(H33="","",J33*H33)))) | J33: 1 | M33: 자외선가시선분광법-싸이오사이안산제이수은법 | Z33: ES 01305.2d | AG33: 0.5 | AH33: ppm | AI33: 1 | AJ33: 염화수소 | AL33: =TYPE(F33) -> 2 | AO33: 염화수소
C34: =IF(ISNUMBER(SEARCH("현대자동차",$E$4)),AO34,AJ34) -> 이황화탄소 | F34: =IF(H34="-","",IF(H34="ND",0,(IF(H34="","",J34*H34)))) | J34: 1 | M34: 자외선/가시선분광법 | Z34: ES 01309.2c | AG34: 1.3 | AH34: ppm | AI34: 1 | AJ34: 이황화탄소 | AL34: =TYPE(F34) -> 2 | AO34: 이황화탄소
C35: =IF(ISNUMBER(SEARCH("현대자동차",$E$4)),AO35,AJ35) -> 황화수소 | F35: =IF(H35="-","",IF(H35="ND",0,(IF(H35="","",J35*H35)))) | J35: 1 | M35: 자외선가시선분광법-메틸렌블루법 | Z35: ES 01310.1d | AG35: 0.5 | AH35: ppm | AI35: 1 | AJ35: 황화수소 | AL35: =TYPE(F35) -> 2 | AO35: 황화수소
C36: =IF(ISNUMBER(SEARCH("현대자동차",$E$4)),AO36,AJ36) -> 플루오린화합물 | F36: =IF(H36="-","",IF(H36="ND",0,(IF(H36="","",J36*H36)))) | J36: 1 | M36: 자외선/가시선분광법-란타넘-알리자린콤플렉손법 | Z36: ES 01311.1f | AG36: 0.02 | AH36: ppm | AI36: 2 | AJ36: 플루오린화합물 | AL36: =TYPE(F36) -> 2 | AO36: 불소화합물
C37: =IF(ISNUMBER(SEARCH("현대자동차",$E$4)),AO37,AJ37) -> 사이안화수소 | F37: =IF(H37="-","",IF(H37="ND",0,(IF(H37="","",J37*H37)))) | J37: 1 | M37: 자외선/가시선분광법- 4-피리딘카복실산-피라졸론법 | Z37: ES 01312.1e | AG37: 0.02 | AH37: ppm | AI37: 2 | AJ37: 사이안화수소 | AL37: =TYPE(F37) -> 2 | AO37: 시안화수소
C38: =IF(ISNUMBER(SEARCH("현대자동차",$E$4)),AO38,AJ38) -> 브로민화합물 | F38: =IF(H38="-","",IF(H38="ND",0,(IF(H38="","",J38*H38)))) | J38: 1 | M38: 자외선/가시선분광법 | Z38: ES 01502.1c | AG38: 0.6 | AH38: ppm | AI38: 1 | AJ38: 브로민화합물 | AL38: =TYPE(F38) -> 2 | AO38: 브롬화합물
C39: =IF(ISNUMBER(SEARCH("현대자동차",$E$4)),AO39,AJ39) -> 페놀화합물 | F39: =IF(H39="-","",IF(H39="ND",0,(IF(H39="","",J39*H39)))) | J39: 1 | M39: 자외선/가시선분광법-4-아미노안티피린법 | Z39: ES 01503.2c | AG39: 0.32 | AH39: ppm | AI39: 2 | AJ39: 페놀화합물 | AL39: =TYPE(F39) -> 2 | AO39: 페놀화합물
C40: 염소 | F40: =IF(H40="-","",IF(H40="ND",0,(IF(H40="","",J40*H40)))) | J40: 1 | M40: 자외선/가시선분광법- 4-피리딘카복실산-피라졸론법 | Z40: ES 01306.2a | AG40: 0.04 | AH40: ppm | AI40: 1 | AJ40: 염소 | AL40: =TYPE(F40) -> 2 | AO40: 염소
F41: =IF(H41="-","",IF(H41="ND",0,(IF(H41="","",J41*H41))))
C42: =IF(ISNUMBER(SEARCH("현대자동차",$E$4)),AO42,AJ42) -> 비소 | F42: =IF(H42="-","",IF(H42="ND",0,(IF(H42="","",J42*H42)))) | J42: 1 | M42: 유도결합플라스마 분광법 | Z42: ES 01401.3e | AG42: 0.001 | AH42: ppm | AI42: 3 | AJ42: 비소 | AL42: =TYPE(F42) -> 2 | AO42: 비소화합물
...

Sheet Sheet1
C5: 성적서 항목명 | D5: 현대차 항목명 | E5: 수식열
C6: 먼지 | D6: 먼지 | E6: =IF(ISNUMBER(SEARCH("현대자동차",'대기측정 분석결과서'!$E$4)),D6,C6) -> 먼지 | F6: 먼지 | H6: 18. | I6: 염화바이닐
C7: 매연 | D7: 매연 | E7: =IF(ISNUMBER(SEARCH("현대자동차",'대기측정 분석결과서'!$E$4)),D7,C7) -> 매연 | F7: 매연 | H7: 19. | I7: 1,3-뷰타다이엔
C8: NOx | D8: 질소산화물 | E8: =IF(ISNUMBER(SEARCH("현대자동차",'대기측정 분석결과서'!$E$4)),D8,C8) -> NOx | F8: 옵티마 | H8: 20. | I8: 다이클로로메테인
C9: SOx | D9: 황산화물 | E9: =IF(ISNUMBER(SEARCH("현대자동차",'대기측정 분석결과서'!$E$4)),D9,C9) -> SOx | F9: 옵티마 | H9: 21. | I9: 아크릴로나이트릴
C10: CO | D10: 일산화탄소 | E10: =IF(ISNUMBER(SEARCH("현대자동차",'대기측정 분석결과서'!$E$4)),D10,C10) -> CO | F10: 옵티마 | H10: 22. | I10: 클로로폼
C11: THC | D11: 탄화수소(THC) | E11: =IF(ISNUMBER(SEARCH("현대자동차",'대기측정 분석결과서'!$E$4)),D11,C11) -> THC | F11: THC | H11: 23. | I11: 사염화탄소
H12: 24. | I12: 벤젠
C13: 암모니아 | D13: 암모니아 | E13: =IF(ISNUMBER(SEARCH("현대자동차",'대기측정 분석결과서'!$E$4)),D13,C13) -> 암모니아 | H13: 25. | I13: 1,2-다이클로로에테인
C14: 염화수소 | D14: 염화수소 | E14: =IF(ISNUMBER(SEARCH("현대자동차",'대기측정 분석결과서'!$E$4)),D14,C14) -> 염화수소 | H14: 26. | I14: 트라이클로로에틸렌
C15: 이황화탄소 | D15: 이황화탄소 | E15: =IF(ISNUMBER(SEARCH("현대자동차",'대기측정 분석결과서'!$E$4)),D15,C15) -> 이황화탄소 | H15: 27. | I15: 톨루엔
C16: 황화수소 | D16: 황화수소 | E16: =IF(ISNUMBER(SEARCH("현대자동차",'대기측정 분석결과서'!$E$4)),D16,C16) -> 황화수소 | H16: 28. | I16: 테트라클로로에틸렌
C17: 플루오린화합물 | D17: 불소화합물 | E17: =IF(ISNUMBER(SEARCH("현대자동차",'대기측정 분석결과서'!$E$4)),D17,C17) -> 플루오린화합물 | H17: 29. | I17: 에틸벤젠
C18: 사이안화수소 | D18: 시안화수소 | E18: =IF(ISNUMBER(SEARCH("현대자동차",'대기측정 분석결과서'!$E$4)),D18,C18) -> 사이안화수소 | H18: 30. | I18: 자일렌
C19: 브로민화합물 | D19: 브롬화합물 | E19: =IF(ISNUMBER(SEARCH("현대자동차",'대기측정 분석결과서'!$E$4)),D19,C19) -> 브로민화합물 | H19: 31. | I19: 스타이렌
C20: 페놀화합물 | D20: 페놀화합물 | E20: =IF(ISNUMBER(SEARCH("현대자동차",'대기측정 분석결과서'!$E$4)),D20,C20) -> 페놀화합물 | H20: 32. | I20: 이황화메틸
C22: 비소 | D22: 비소화합물 | E22: =IF(ISNUMBER(SEARCH("현대자동차",'대기측정 분석결과서'!$E$4)),D22,C22) -> 비소 | F22: 중금속 | H22: 33. | I22: 폼알데하이드
C23: 카드뮴 | D23: 카드뮴화합물 | E23: =IF(ISNUMBER(SEARCH("현대자동차",'대기측정 분석결과서'!$E$4)),D23,C23) -> 카드뮴 | F23: 중금속 | H23: 34. | I23: 아세트알데하이드
C24: 납 | D24: 납화합물 | E24: =IF(ISNUMBER(SEARCH("현대자동차",'대기측정 분석결과서'!$E$4)),D24,C24) -> 납 | F24: 중금속 | H24: 35. | I24: 아크롤레인
C25: 크로뮴 | D25: 크롬화합물 | E25: =IF(ISNUMBER(SEARCH("현대자동차",'대기측정 분석결과서'!$E$4)),D25,C25) -> 크로뮴 | F25: 중금속
C26: 구리 | D26: 구리화합물 | E26: =IF(ISNUMBER(SEARCH("현대자동차",'대기측정 분석결과서'!$E$4)),D26,C26) -> 구리 | F26: 중금속
C27: 니켈 | D27: 니켈화합물 | E27: =IF(ISNUMBER(SEARCH("현대자동차",'대기측정 분석결과서'!$E$4)),D27,C27) -> 니켈 | F27: 중금속
C28: 아연 | D28: 아연화합물 | E28: =IF(ISNUMBER(SEARCH("현대자동차",'대기측정 분석결과서'!$E$4)),D28,C28) -> 아연 | F28: 중금속
C29: 수은 | D29: 수은화합물 | E29: =IF(ISNUMBER(SEARCH("현대자동차",'대기측정 분석결과서'!$E$4)),D29,C29) -> 수은 | F29: 수은
C30: 베릴륨 | D30: 베릴륨 및 그 화합물 | E30: =IF(ISNUMBER(SEARCH("현대자동차",'대기측정 분석결과서'!$E$4)),D30,C30) -> 베릴륨 | F30: 중금속
C32: 염화바이닐 | D32: 염화비닐 | E32: =IF(ISNUMBER(SEARCH("현대자동차",'대기측정 분석결과서'!$E$4)),D32,C32) -> 염화바이닐 | F32: A
C33: 1,3-뷰타다이엔 | D33: 1,3-부타디엔 | E33: =IF(ISNUMBER(SEARCH("현대자동차",'대기측정 분석결과서'!$E$4)),D33,C33) -> 1,3-뷰타다이엔 | F33: A
C34: 다이클로로메테인 | D34: 디클로로메탄 | E34: =IF(ISNUMBER(SEARCH("현대자동차",'대기측정 분석결과서'!$E$4)),D34,C34) -> 다이클로로메테인 | F34: T
C35: 아크릴로나이트릴 | D35: 아크릴로니트릴 | E35: =IF(ISNUMBER(SEARCH("현대자동차",'대기측정 분석결과서'!$E$4)),D35,C35) -> 아크릴로나이트릴 | F35: T
C36: 클로로폼 | D36: 클로로포름 | E36: =IF(ISNUMBER(SEARCH("현대자동차",'대기측정 분석결과서'!$E$4)),D36,C36) -> 클로로폼 | F36: T
C37: 사염화탄소 | D37: 사염화탄소 | E37: =IF(ISNUMBER(SEARCH("현대자동차",'대기측정 분석결과서'!$E$4)),D37,C37) -> 사염화탄소 | F37: A
... C51: 아크롤레인 | D51: 아크롤레인 | E51: =IF(ISNUMBER(SEARCH("현대자동차",'대기측정 분석결과서'!$E$4)),D51,C51) -> 아크롤레인 | F51: DNPH

Sheet 대기측정기록부
A1: [별지 제21호 서식] | T1: ="접수번호 : KGAR-"&RIGHT(YEAR('먼지측정 사전 Data'!N6),2)&"-"&'먼지측정 사전 Data'!O4 -> 접수번호 : KGAR-26-
A2: 대 기 측 정 기 록 부
A3: ①의뢰인 | B3: 상 호 (기관명) | F3: ='대기측정 분석결과서'!E4 -> 0 | L3: ② 일 반 현 황 | M3: 업 종 | P3: ='대기측정 분석결과서'!L6 -> 0 | W3: 기술인력
B4: 소 재 지 (주 소) | F4: ='대기측정 분석결과서'!E5 -> 0 | M4: 시설 종류 | P4: =IF('대기측정 분석결과서'!E12="",B23,'대기측정 분석결과서'!E12) -> 0 | W4: 맹호수 | Y4: 박민우 | AA4: 이동협 | AC4: 정우창 | AE4: 신민석 | AG4: 강민수 | AI4: 강원석 | AK4: 정종원 | AL4: 김흥록 | AM4: 송정현
B5: 대 표 자 (의뢰인) | F5: ='대기측정 분석결과서'!E6 -> 0 | M5: 사업장 종별 | P5: ='대기측정 분석결과서'!E10&" 종" -> 종
B6: 환 경 기 술 인 | F6: ='대기측정 분석결과서'!E7 -> 여 형 석
A7: ③의뢰내용 | B7: 측 정 용 도 | F7: ="자가 측정용" -> 자가 측정용 | W7: 품책 | Y7: 대기기책 | AC7: 현재분책
B8: 굴 뚝 | F8: 굴뚝 명칭 | M8: 높이 [m] | O8: 안지름(측정공) [m] | S8: 굴뚝 종별 [종] | W8: 진수일 | Y8: 이나영 | AC8: 이나영 | AG8: 김태우 | AI8: 백희석 | AK8: 김인현
F9: ='대기측정 분석결과서'!E9 -> 0 | M9: ='한종_시료채취기록지 '!N3&" m" -> 0 m | O9: =IF(LEN('한종_시료채취기록지 '!F9)=1,'한종_시료채취기록지 '!F9&".000 m", IF(LEN('한종_시료채취기록지 '!F9)=3,'한종_시료채취기록지 '!F9&"00 m", IF(LEN('한종_시료채취기록지 '!F9)=4,'한종_시료채취기록지 '!F9&"0 m", '한종_시료채취기록지 '!F9&" m"))) -> 0.000 X 0.000 m | S9: ='대기측정 분석결과서'!E11&" 종" -> 종
B10: 의 뢰 항 목 | F10: ='대기측정 분석결과서'!U11 -> THC (총 1 항목)
A11: ④시료채취 | B11: 현 장 기 상 | F11: 날씨 | H11: 기온 [℃] | J11: 습도 [%] | M11: 기압 [mmHg] | P11: 풍향 [풍] | S11: 풍속 [m/s] | W11: *분석기술인 -> 기술책임자
F12: ='대기측정 분석결과서'!E17 -> 0 | H12: ='대기측정 분석결과서'!I17 -> 0 | J12: ='대기측정 분석결과서'!M17 -> 0 | M12: ='대기측정 분석결과서'!Q17 -> 0 | P12: ='대기측정 분석결과서'!V17 -> 0 | S12: ='대기측정 분석결과서'!AA17 -> 0
B13: 배 출 가 스 | F13: 표준산소농도 | I13: 실측산소농도 | M13: 배출가스유량(산소보정 전) | R13: 배출가스유량(산소보정 후)
F14: =IF('먼지측정 사전 Data'!R13=20.9,"-",'먼지측정 사전 Data'!R13&" %") -> - | I14: ='먼지측정 사전 Data'!H14&" %" -> 0 % | M14: ='시험일지(계산일지-2)'!R11&" S㎥/분" -> #DIV/0! | R14: ='시험일지(계산일지-2)'!Q21&" S㎥/분" -> #DIV/0!
F15: 수분량 | I15: 배출가스온도 | M15: 배출가스 유속 | R15: 기타
F16: ='먼지측정 사전 Data'!H59&" %" -> #DIV/0! | I16: ='먼지측정 사전 Data'!R69&" ℃" -> #DIV/0! | M16: ='먼지측정 사전 Data'!R82&" m/s" -> #DIV/0! | R16: -
B17: 방 지 시 설 | F17: 명 칭 | M17: 대 상 물 질 | R17: 방 지 효 율
F18: ='대기측정 분석결과서'!E13&IF('대기측정 분석결과서'!L10="",""," ("&'대기측정 분석결과서'!L10&")") | M18: - | R18: - | T18: %
B19: 채 취 일 시 | F19: 채취일 | H19: ='먼지측정 사전 Data'!N5 -> 0 | M19: 시료채취자 | Q19: ='대기측정 분석결과서'!U7&" (서명)" -> 0 (서명)
F20: 채취시간 | H20: ='먼지측정 사전 Data'!H6&" : "&IF('먼지측정 사전 Data'!I6<10,"0"&'먼지측정 사전 Data'!I6,'먼지측정 사전 Data'!I6)&" ~ "&'먼지측정 사전 Data'!K6&" : "&IF('먼지측정 사전 Data'!L6<10,"0"&'먼지측정 사전 Data'!L6,'먼지측정 사전 Data'!L6) -> : 0 ~ : 0 | Q20: ='대기측정 분석결과서'!X7&" (서명)" -> 0 (서명)
A21: ⑤ 시 설 가 동 상 황 | B21: 배출시설 명칭 | F21: 측정당시 시간당 사용(생산)량 | R21: 방지시설 명칭
F22: 연료사용량 | H22: 제품생산량 | J22: 소각량 | L22: 원료투입량 | N22: 종류 | P22: 단위
B23: ='대기측정 분석결과서'!E9 -> 0 | F23: ='대기측정 분석결과서'!L11 -> - | H23: - | J23: - | L23: - | N23: =IF(F23="-","-","LNG") -> - | P23: ='대기측정 분석결과서'!N11 -> Kg/Hr | R23: =IF(F18=0,"",'대기측정 분석결과서'!E13) -> 0
A24: ⑥측정분석결과 | B24: 측 정 항 목 | F24: 허용 기준 | I24: 측정분석값 | L24: 측정시간 | O24: 측정분석방법 (기기명) | S24: 비고
F26: =IF(B26="","","??") | H26: =IF(B26="","",INDEX('대기측정 분석결과서'!$AH$23:$AH$74,MATCH(B26,측정항목,0))) | I26: =IF(B26="","", IF(INDEX('대기측정 분석결과서'!$F$23:$I$74,MATCH(B26,항목,0),1)="","값없음", IF(ISERROR(FIXED(IF(INDEX('대기측정 분석결과서'!$F$23:$I$74,MATCH(B26,항목,0),1)<INDEX('대기측정 분석결과서'!$AG$23:$AG$74,MATCH(B26,항목,0)),"불검출", INDEX('대기측정 분석결과서'!$F$23:$I$74,MATCH(B26,항목,0),1)),INDEX('대기측정 분석결과서'!$AI$23:$AI$74,MATCH(B26,항목,0)))),"불검출", FIXED(INDEX('대기측정 분석결과서'!$F$23:$I$74,MATCH(B26,항목,0),1),INDEX('대기측정 분석결과서'!$AI$23:$AI$74,MATCH(B26,항목,0)))))) | L26: =IF(B26="","", IF(INDEX(Sheet1!$E$6:$F$51,MATCH(B26,Sheet1!$E$6:$E$51,0),2)="수은", '한종_시료채취기록지 '!$AG$20, IF(INDEX(Sheet1!$E$6:$F$51,MATCH(B26,Sheet1!$E$6:$E$51,0),2)="먼지", '한종_시료채취기록지 '!$Y$20, IF(INDEX(Sheet1!$E$6:$F$51,MATCH(B26,Sheet1!$E$6:$E$51,0),2)="THC", '한종_시료채취기록지 '!$AC$23, IF(INDEX(Sheet1!$E$6:$F$51,MATCH(B26,Sheet1!$E$6:$E$51,0),2)="매연", '한종_시료채취기록지 '!$AG$23, IF(INDEX(Sheet1!$E$6:$F$51,MATCH(B26,Sheet1!$E$6:$E$51,0),2)="옵티마", '한종_시료채취기록지 '!$Y$23, IF(INDEX(Sheet1!$E$6:$F$51,MATCH(B26,Sheet1!$E$6:$E$51,0),2)="중금속", '한종_시료채취기록지 '!$AC$20, IF(INDEX(Sheet1!$E$6:$F$51,MATCH(B26,Sheet1!$E$6:$E$51,0),2)="T", IFERROR( INDEX(가스상항목시간,MATCH("VOCs-T",가스상항목,0),5), INDEX(가스상항목시간,MATCH("VOCs-A",가스상항목,0),5) ), IF(INDEX(Sheet1!$E$6:$F$51,MATCH(B26,Sheet1!$E$6:$E$51,0),2)="A", INDEX(가스상항목시간,MATCH("VOCs-A",가스상항목,0),5), IF(INDEX(Sheet1!$E$6:$F$51,MATCH(B26,Sheet1!$E$6:$E$51,0),2)="DNPH", INDEX(가스상항목시간,MATCH("VOCs",가스상항목,0),5), INDEX(가스상항목시간,MATCH(B26,가스상항목,0),5) )))))))))) | O26: =IF(B26="","",INDEX('대기측정 분석결과서'!$Z$23:$Z$74,MATCH(B26,항목,0))) | S26: =IF(B26="","",INDEX('대기측정 분석결과서'!$M$23:$M$74,MATCH(B26,항목,0))) | V26: -이하여백-
F27: =IF(B27="","","??") | H27: =IF(B27="","",INDEX('대기측정 분석결과서'!$AH$23:$AH$74,MATCH(B27,측정항목,0))) | I27: =IF(B27="","", IF(INDEX('대기측정 분석결과서'!$F$23:$I$74,MATCH(B27,항목,0),1)="","값없음", IF(ISERROR(FIXED(IF(INDEX('대기측정 분석결과서'!$F$23:$I$74,MATCH(B27,항목,0),1)<INDEX('대기측정 분석결과서'!$AG$23:$AG$74,MATCH(B27,항목,0)),"불검출", INDEX('대기측정 분석결과서'!$F$23:$I$74,MATCH(B27,항목,0),1)),INDEX('대기측정 분석결과서'!$AI$23:$AI$74,MATCH(B27,항목,0)))),"불검출", FIXED(INDEX('대기측정 분석결과서'!$F$23:$I$74,MATCH(B27,항목,0),1),INDEX('대기측정 분석결과서'!$AI$23:$AI$74,MATCH(B27,항목,0)))))) | L27: =IF(B27="","", IF(INDEX(Sheet1!$E$6:$F$51,MATCH(B27,Sheet1!$E$6:$E$51,0),2)="수은", '한종_시료채취기록지 '!$AG$20, IF(INDEX(Sheet1!$E$6:$F$51,MATCH(B27,Sheet1!$E$6:$E$51,0),2)="먼지", '한종_시료채취기록지 '!$Y$20, IF(INDEX(Sheet1!$E$6:$F$51,MATCH(B27,Sheet1!$E$6:$E$51,0),2)="THC", '한종_시료채취기록지 '!$AC$23, IF(INDEX(Sheet1!$E$6:$F$51,MATCH(B27,Sheet1!$E$6:$E$51,0),2)="매연", '한종_시료채취기록지 '!$AG$23, IF(INDEX(Sheet1!$E$6:$F$51,MATCH(B27,Sheet1!$E$6:$E$51,0),2)="옵티마", '한종_시료채취기록지 '!$Y$23, IF(INDEX(Sheet1!$E$6:$F$51,MATCH(B27,Sheet1!$E$6:$E$51,0),2)="중금속", '한종_시료채취기록지 '!$AC$20, IF(INDEX(Sheet1!$E$6:$F$51,MATCH(B27,Sheet1!$E$6:$E$51,0),2)="T", IFERROR( INDEX(가스상항목시간,MATCH("VOCs-T",가스상항목,0),5), INDEX(가스상항목시간,MATCH("VOCs-A",가스상항목,0),5) ), IF(INDEX(Sheet1!$E$6:$F$51,MATCH(B27,Sheet1!$E$6:$E$51,0),2)="A", INDEX(가스상항목시간,MATCH("VOCs-A",가스상항목,0),5), IF(INDEX(Sheet1!$E$6:$F$51,MATCH(B27,Sheet1!$E$6:$E$51,0),2)="DNPH", INDEX(가스상항목시간,MATCH("VOCs",가스상항목,0),5), INDEX(가스상항목시간,MATCH(B27,가스상항목,0),5) )))))))))) | O27: =IF(B27="","",INDEX('대기측정 분석결과서'!$Z$23:$Z$74,MATCH(B27,항목,0))) | S27: =IF(B27="","",INDEX('대기측정 분석결과서'!$M$23:$M$74,MATCH(B27,항목,0)))
F28: =IF(B28="","","??") | H28: =IF(B28="","",INDEX('대기측정 분석결과서'!$AH$23:$AH$74,MATCH(B28,측정항목,0))) | I28: =IF(B28="","", IF(INDEX('대기측정 분석결과서'!$F$23:$I$74,MATCH(B28,항목,0),1)="","값없음", IF(ISERROR(FIXED(IF(INDEX('대기측정 분석결과서'!$F$23:$I$74,MATCH(B28,항목,0),1)<INDEX('대기측정 분석결과서'!$AG$23:$AG$74,MATCH(B28,항목,0)),"불검출", INDEX('대기측정 분석결과서'!$F$23:$I$74,MATCH(B28,항목,0),1)),INDEX('대기측정 분석결과서'!$AI$23:$AI$74,MATCH(B28,항목,0)))),"불검출", FIXED(INDEX('대기측정 분석결과서'!$F$23:$I$74,MATCH(B28,항목,0),1),INDEX('대기측정 분석결과서'!$AI$23:$AI$74,MATCH(B28,항목,0)))))) | L28: =IF(B28="","", IF(INDEX(Sheet1!$E$6:$F$51,MATCH(B28,Sheet1!$E$6:$E$51,0),2)="수은", '한종_시료채취기록지 '!$AG$20, IF(INDEX(Sheet1!$E$6:$F$51,MATCH(B28,Sheet1!$E$6:$E$51,0),2)="먼지", '한종_시료채취기록지 '!$Y$20, IF(INDEX(Sheet1!$E$6:$F$51,MATCH(B28,Sheet1!$E$6:$E$51,0),2)="THC", '한종_시료채취기록지 '!$AC$23, IF(INDEX(Sheet1!$E$6:$F$51,MATCH(B28,Sheet1!$E$6:$E$51,0),2)="매연", '한종_시료채취기록지 '!$AG$23, IF(INDEX(Sheet1!$E$6:$F$51,MATCH(B28,Sheet1!$E$6:$E$51,0),2)="옵티마", '한종_시료채취기록지 '!$Y$23, IF(INDEX(Sheet1!$E$6:$F$51,MATCH(B28,Sheet1!$E$6:$E$51,0),2)="중금속", '한종_시료채취기록지 '!$AC$20, IF(INDEX(Sheet1!$E$6:$F$51,MATCH(B28,Sheet1!$E$6:$E$51,0),2)="T", IFERROR( INDEX(가스상항목시간,MATCH("VOCs-T",가스상항목,0),5), INDEX(가스상항목시간,MATCH("VOCs-A",가스상항목,0),5) ), IF(INDEX(Sheet1!$E$6:$F$51,MATCH(B28,Sheet1!$E$6:$E$51,0),2)="A", INDEX(가스상항목시간,MATCH("VOCs-A",가스상항목,0),5), IF(INDEX(Sheet1!$E$6:$F$51,MATCH(B28,Sheet1!$E$6:$E$51,0),2)="DNPH", INDEX(가스상항목시간,MATCH("VOCs",가스상항목,0),5), INDEX(가스상항목시간,MATCH(B28,가스상항목,0),5) )))))))))) | O28: =IF(B28="","",INDEX('대기측정 분석결과서'!$Z$23:$Z$74,MATCH(B28,항목,0))) | S28: =IF(B28="","",INDEX('대기측정 분석결과서'!$M$23:$M$74,MATCH(B28,항목,0)))
F29: =IF(B29="","","??") | H29: =IF(B29="","",INDEX('대기측정 분석결과서'!$AH$23:$AH$74,MATCH(B29,측정항목,0))) | I29: =IF(B29="","", IF(INDEX('대기측정 분석결과서'!$F$23:$I$74,MATCH(B29,항목,0),1)="","값없음", IF(ISERROR(FIXED(IF(INDEX('대기측정 분석결과서'!$F$23:$I$74,MATCH(B29,항목,0),1)<INDEX('대기측정 분석결과서'!$AG$23:$AG$74,MATCH(B29,항목,0)),"불검출", INDEX('대기측정 분석결과서'!$F$23:$I$74,MATCH(B29,항목,0),1)),INDEX('대기측정 분석결과서'!$AI$23:$AI$74,MATCH(B29,항목,0)))),"불검출", FIXED(INDEX('대기측정 분석결과서'!$F$23:$I$74,MATCH(B29,항목,0),1),INDEX('대기측정 분석결과서'!$AI$23:$AI$74,MATCH(B29,항목,0)))))) | L29: =IF(B29="","", IF(INDEX(Sheet1!$E$6:$F$51,MATCH(B29,Sheet1!$E$6:$E$51,0),2)="수은", '한종_시료채취기록지 '!$AG$20, IF(INDEX(Sheet1!$E$6:$F$51,MATCH(B29,Sheet1!$E$6:$E$51,0),2)="먼지", '한종_시료채취기록지 '!$Y$20, IF(INDEX(Sheet1!$E$6:$F$51,MATCH(B29,Sheet1!$E$6:$E$51,0),2)="THC", '한종_시료채취기록지 '!$AC$23, IF(INDEX(Sheet1!$E$6:$F$51,MATCH(B29,Sheet1!$E$6:$E$51,0),2)="매연", '한종_시료채취기록지 '!$AG$23, IF(INDEX(Sheet1!$E$6:$F$51,MATCH(B29,Sheet1!$E$6:$E$51,0),2)="옵티마", '한종_시료채취기록지 '!$Y$23, IF(INDEX(Sheet1!$E$6:$F$51,MATCH(B29,Sheet1!$E$6:$E$51,0),2)="중금속", '한종_시료채취기록지 '!$AC$20, IF(INDEX(Sheet1!$E$6:$F$51,MATCH(B29,Sheet1!$E$6:$E$51,0),2)="T", IFERROR( INDEX(가스상항목시간,MATCH("VOCs-T",가스상항목,0),5), INDEX(가스상항목시간,MATCH("VOCs-A",가스상항목,0),5) ), IF(INDEX(Sheet1!$E$6:$F$51,MATCH(B29,Sheet1!$E$6:$E$51,0),2)="A", INDEX(가스상항목시간,MATCH("VOCs-A",가스상항목,0),5), IF(INDEX(Sheet1!$E$6:$F$51,MATCH(B29,Sheet1!$E$6:$E$51,0),2)="DNPH", INDEX(가스상항목시간,MATCH("VOCs",가스상항목,0),5), INDEX(가스상항목시간,MATCH(B29,가스상항목,0),5) )))))))))) | O29: =IF(B29="","",INDEX('대기측정 분석결과서'!$Z$23:$Z$74,MATCH(B29,항목,0))) | S29: =IF(B29="","",INDEX('대기측정 분석결과서'!$M$23:$M$74,MATCH(B29,항목,0)))
F30: =IF(B30="","","??") | H30: =IF(B30="","",INDEX('대기측정 분석결과서'!$AH$23:$AH$74,MATCH(B30,측정항목,0))) | I30: =IF(B30="","", IF(INDEX('대기측정 분석결과서'!$F$23:$I$74,MATCH(B30,항목,0),1)="","값없음", IF(ISERROR(FIXED(IF(INDEX('대기측정 분석결과서'!$F$23:$I$74,MATCH(B30,항목,0),1)<INDEX('대기측정 분석결과서'!$AG$23:$AG$74,MATCH(B30,항목,0)),"불검출", INDEX('대기측정 분석결과서'!$F$23:$I$74,MATCH(B30,항목,0),1)),INDEX('대기측정 분석결과서'!$AI$23:$AI$74,MATCH(B30,항목,0)))),"불검출", FIXED(INDEX('대기측정 분석결과서'!$F$23:$I$74,MATCH(B30,항목,0),1),INDEX('대기측정 분석결과서'!$AI$23:$AI$74,MATCH(B30,항목,0)))))) | L30: =IF(B30="","", IF(INDEX(Sheet1!$E$6:$F$51,MATCH(B30,Sheet1!$E$6:$E$51,0),2)="수은", '한종_시료채취기록지 '!$AG$20, IF(INDEX(Sheet1!$E$6:$F$51,MATCH(B30,Sheet1!$E$6:$E$51,0),2)="먼지", '한종_시료채취기록지 '!$Y$20, IF(INDEX(Sheet1!$E$6:$F$51,MATCH(B30,Sheet1!$E$6:$E$51,0),2)="THC", '한종_시료채취기록지 '!$AC$23, IF(INDEX(Sheet1!$E$6:$F$51,MATCH(B30,Sheet1!$E$6:$E$51,0),2)="매연", '한종_시료채취기록지 '!$AG$23, IF(INDEX(Sheet1!$E$6:$F$51,MATCH(B30,Sheet1!$E$6:$E$51,0),2)="옵티마", '한종_시료채취기록지 '!$Y$23, IF(INDEX(Sheet1!$E$6:$F$51,MATCH(B30,Sheet1!$E$6:$E$51,0),2)="중금속", '한종_시료채취기록지 '!$AC$20, IF(INDEX(Sheet1!$E$6:$F$51,MATCH(B30,Sheet1!$E$6:$E$51,0),2)="T", IFERROR( INDEX(가스상항목시간,MATCH("VOCs-T",가스상항목,0),5), INDEX(가스상항목시간,MATCH("VOCs-A",가스상항목,0),5) ), IF(INDEX(Sheet1!$E$6:$F$51,MATCH(B30,Sheet1!$E$6:$E$51,0),2)="A", INDEX(가스상항목시간,MATCH("VOCs-A",가스상항목,0),5), IF(INDEX(Sheet1!$E$6:$F$51,MATCH(B30,Sheet1!$E$6:$E$51,0),2)="DNPH", INDEX(가스상항목시간,MATCH("VOCs",가스상항목,0),5), INDEX(가스상항목시간,MATCH(B30,가스상항목,0),5) )))))))))) | O30: =IF(B30="","",INDEX('대기측정 분석결과서'!$Z$23:$Z$74,MATCH(B30,항목,0))) | S30: =IF(B30="","",INDEX('대기측정 분석결과서'!$M$23:$M$74,MATCH(B30,항목,0)))
F31: =IF(B31="","","??") | H31: =IF(B31="","",INDEX('대기측정 분석결과서'!$AH$23:$AH$74,MATCH(B31,측정항목,0))) | I31: =IF(B31="","", IF(INDEX('대기측정 분석결과서'!$F$23:$I$74,MATCH(B31,항목,0),1)="","값없음", IF(ISERROR(FIXED(IF(INDEX('대기측정 분석결과서'!$F$23:$I$74,MATCH(B31,항목,0),1)<INDEX('대기측정 분석결과서'!$AG$23:$AG$74,MATCH(B31,항목,0)),"불검출", INDEX('대기측정 분석결과서'!$F$23:$I$74,MATCH(B31,항목,0),1)),INDEX('대기측정 분석결과서'!$AI$23:$AI$74,MATCH(B31,항목,0)))),"불검출", FIXED(INDEX('대기측정 분석결과서'!$F$23:$I$74,MATCH(B31,항목,0),1),INDEX('대기측정 분석결과서'!$AI$23:$AI$74,MATCH(B31,항목,0)))))) | L31: =IF(B31="","", IF(INDEX(Sheet1!$E$6:$F$51,MATCH(B31,Sheet1!$E$6:$E$51,0),2)="수은", '한종_시료채취기록지 '!$AG$20, IF(INDEX(Sheet1!$E$6:$F$51,MATCH(B31,Sheet1!$E$6:$E$51,0),2)="먼지", '한종_시료채취기록지 '!$Y$20, IF(INDEX(Sheet1!$E$6:$F$51,MATCH(B31,Sheet1!$E$6:$E$51,0),2)="THC", '한종_시료채취기록지 '!$AC$23, IF(INDEX(Sheet1!$E$6:$F$51,MATCH(B31,Sheet1!$E$6:$E$51,0),2)="매연", '한종_시료채취기록지 '!$AG$23, IF(INDEX(Sheet1!$E$6:$F$51,MATCH(B31,Sheet1!$E$6:$E$51,0),2)="옵티마", '한종_시료채취기록지 '!$Y$23, IF(INDEX(Sheet1!$E$6:$F$51,MATCH(B31,Sheet1!$E$6:$E$51,0),2)="중금속", '한종_시료채취기록지 '!$AC$20, IF(INDEX(Sheet1!$E$6:$F$51,MATCH(B31,Sheet1!$E$6:$E$51,0),2)="T", IFERROR( INDEX(가스상항목시간,MATCH("VOCs-T",가스상항목,0),5), INDEX(가스상항목시간,MATCH("VOCs-A",가스상항목,0),5) ), IF(INDEX(Sheet1!$E$6:$F$51,MATCH(B31,Sheet1!$E$6:$E$51,0),2)="A", INDEX(가스상항목시간,MATCH("VOCs-A",가스상항목,0),5), IF(INDEX(Sheet1!$E$6:$F$51,MATCH(B31,Sheet1!$E$6:$E$51,0),2)="DNPH", INDEX(가스상항목시간,MATCH("VOCs",가스상항목,0),5), INDEX(가스상항목시간,MATCH(B31,가스상항목,0),5) )))))))))) | O31: =IF(B31="","",INDEX('대기측정 분석결과서'!$Z$23:$Z$74,MATCH(B31,항목,0))) | S31: =IF(B31="","",INDEX('대기측정 분석결과서'!$M$23:$M$74,MATCH(B31,항목,0)))
F32: =IF(B32="","","??") | H32: =IF(B32="","",INDEX('대기측정 분석결과서'!$AH$23:$AH$74,MATCH(B32,측정항목,0))) | I32: =IF(B32="","", IF(INDEX('대기측정 분석결과서'!$F$23:$I$74,MATCH(B32,항목,0),1)="","값없음", IF(ISERROR(FIXED(IF(INDEX('대기측정 분석결과서'!$F$23:$I$74,MATCH(B32,항목,0),1)<INDEX('대기측정 분석결과서'!$AG$23:$AG$74,MATCH(B32,항목,0)),"불검출", INDEX('대기측정 분석결과서'!$F$23:$I$74,MATCH(B32,항목,0),1)),INDEX('대기측정 분석결과서'!$AI$23:$AI$74,MATCH(B32,항목,0)))),"불검출", FIXED(INDEX('대기측정 분석결과서'!$F$23:$I$74,MATCH(B32,항목,0),1),INDEX('대기측정 분석결과서'!$AI$23:$AI$74,MATCH(B32,항목,0)))))) | L32: =IF(B32="","", IF(INDEX(Sheet1!$E$6:$F$51,MATCH(B32,Sheet1!$E$6:$E$51,0),2)="수은", '한종_시료채취기록지 '!$AG$20, IF(INDEX(Sheet1!$E$6:$F$51,MATCH(B32,Sheet1!$E$6:$E$51,0),2)="먼지", '한종_시료채취기록지 '!$Y$20, IF(INDEX(Sheet1!$E$6:$F$51,MATCH(B32,Sheet1!$E$6:$E$51,0),2)="THC", '한종_시료채취기록지 '!$AC$23, IF(INDEX(Sheet1!$E$6:$F$51,MATCH(B32,Sheet1!$E$6:$E$51,0),2)="매연", '한종_시료채취기록지 '!$AG$23, IF(INDEX(Sheet1!$E$6:$F$51,MATCH(B32,Sheet1!$E$6:$E$51,0),2)="옵티마", '한종_시료채취기록지 '!$Y$23, IF(INDEX(Sheet1!$E$6:$F$51,MATCH(B32,Sheet1!$E$6:$E$51,0),2)="중금속", '한종_시료채취기록지 '!$AC$20, IF(INDEX(Sheet1!$E$6:$F$51,MATCH(B32,Sheet1!$E$6:$E$51,0),2)="T", IFERROR( INDEX(가스상항목시간,MATCH("VOCs-T",가스상항목,0),5), INDEX(가스상항목시간,MATCH("VOCs-A",가스상항목,0),5) ), IF(INDEX(Sheet1!$E$6:$F$51,MATCH(B32,Sheet1!$E$6:$E$51,0),2)="A", INDEX(가스상항목시간,MATCH("VOCs-A",가스상항목,0),5), IF(INDEX(Sheet1!$E$6:$F$51,MATCH(B32,Sheet1!$E$6:$E$51,0),2)="DNPH", INDEX(가스상항목시간,MATCH("VOCs",가스상항목,0),5), INDEX(가스상항목시간,MATCH(B32,가스상항목,0),5) )))))))))) | O32: =IF(B32="","",INDEX('대기측정 분석결과서'!$Z$23:$Z$74,MATCH(B32,항목,0))) | S32: =IF(B32="","",INDEX('대기측정 분석결과서'!$M$23:$M$74,MATCH(B32,항목,0)))
F33: =IF(B33="","","??") | H33: =IF(B33="","",INDEX('대기측정 분석결과서'!$AH$23:$AH$74,MATCH(B33,측정항목,0))) | I33: =IF(B33="","", IF(INDEX('대기측정 분석결과서'!$F$23:$I$74,MATCH(B33,항목,0),1)="","값없음", IF(ISERROR(FIXED(IF(INDEX('대기측정 분석결과서'!$F$23:$I$74,MATCH(B33,항목,0),1)<INDEX('대기측정 분석결과서'!$AG$23:$AG$74,MATCH(B33,항목,0)),"불검출", INDEX('대기측정 분석결과서'!$F$23:$I$74,MATCH(B33,항목,0),1)),INDEX('대기측정 분석결과서'!$AI$23:$AI$74,MATCH(B33,항목,0)))),"불검출", FIXED(INDEX('대기측정 분석결과서'!$F$23:$I$74,MATCH(B33,항목,0),1),INDEX('대기측정 분석결과서'!$AI$23:$AI$74,MATCH(B33,항목,0)))))) | L33: =IF(B33="","", IF(INDEX(Sheet1!$E$6:$F$51,MATCH(B33,Sheet1!$E$6:$E$51,0),2)="수은", '한종_시료채취기록지 '!$AG$20, IF(INDEX(Sheet1!$E$6:$F$51,MATCH(B33,Sheet1!$E$6:$E$51,0),2)="먼지", '한종_시료채취기록지 '!$Y$20, IF(INDEX(Sheet1!$E$6:$F$51,MATCH(B33,Sheet1!$E$6:$E$51,0),2)="THC", '한종_시료채취기록지 '!$AC$23, IF(INDEX(Sheet1!$E$6:$F$51,MATCH(B33,Sheet1!$E$6:$E$51,0),2)="매연", '한종_시료채취기록지 '!$AG$23, IF(INDEX(Sheet1!$E$6:$F$51,MATCH(B33,Sheet1!$E$6:$E$51,0),2)="옵티마", '한종_시료채취기록지 '!$Y$23, IF(INDEX(Sheet1!$E$6:$F$51,MATCH(B33,Sheet1!$E$6:$E$51,0),2)="중금속", '한종_시료채취기록지 '!$AC$20, IF(INDEX(Sheet1!$E$6:$F$51,MATCH(B33,Sheet1!$E$6:$E$51,0),2)="T", IFERROR( INDEX(가스상항목시간,MATCH("VOCs-T",가스상항목,0),5), INDEX(가스상항목시간,MATCH("VOCs-A",가스상항목,0),5) ), IF(INDEX(Sheet1!$E$6:$F$51,MATCH(B33,Sheet1!$E$6:$E$51,0),2)="A", INDEX(가스상항목시간,MATCH("VOCs-A",가스상항목,0),5), IF(INDEX(Sheet1!$E$6:$F$51,MATCH(B33,Sheet1!$E$6:$E$51,0),2)="DNPH", INDEX(가스상항목시간,MATCH("VOCs",가스상항목,0),5), INDEX(가스상항목시간,MATCH(B33,가스상항목,0),5) )))))))))) | O33: =IF(B33="","",INDEX('대기측정 분석결과서'!$Z$23:$Z$74,MATCH(B33,항목,0))) | S33: =IF(B33="","",INDEX('대기측정 분석결과서'!$M$23:$M$74,MATCH(B33,항목,0)))
B34: 분 석 기 간 | F34: ='먼지측정 사전 Data'!H5 -> 2026-02-06 ~ 1900-01-00 | M34: 분석기술인 | Q34: 책임기술인과 같음
M35: 책임기술인 | Q35: 이 나 영 | T35: (인)
A36: ⑦ 종 합 의 견 | H36: 배 출 허 용 기 준 에 | L36: 적합 | Q36: .
A37: 위와 같이 측정분석결과를 사실대로 기록합니다.
K38: =YEAR('먼지측정 사전 Data'!R6) -> 2026 | M38: 년 | O38: =MONTH('먼지측정 사전 Data'!R6) -> 2 | P38: 월 | R38: =DAY('먼지측정 사전 Data'!R6) -> 13 | S38: 일 | X38: 발행일
C39: 상 호 | H39: 한 국 종 합 환 경 산 업 ㈜
C40: 소재지 및 연락처 | H40: 부산광역시 강서구 대저중앙로394번가길 56(대저1동), 051-555-6511
C41: 대 표 자 성 명 | H41: 김항재 | S41: (서명 또는 인)
...

Sheet 대기측정기록부(2페이지)
A1: [별지 제21호 서식] | T1: ="접수번호 : KGAR-"&RIGHT(YEAR('먼지측정 사전 Data'!N6),2)&"-"&'먼지측정 사전 Data'!O4 -> 접수번호 : KGAR-26-
A2: 대 기 측 정 기 록 부
A3: ①의뢰인 | B3: 상 호 (기관명) | F3: ='대기측정 분석결과서'!E4 -> 0 | L3: ② 일 반 현 황 | M3: 업 종 | P3: ='대기측정 분석결과서'!L6 -> 0
B4: 소 재 지 (주 소) | F4: ='대기측정 분석결과서'!E5 -> 0 | M4: 시설 종류 | P4: =IF('대기측정 분석결과서'!E12="",B23,'대기측정 분석결과서'!E12) -> 0 | W4: 기술인력
B5: 대 표 자 (의뢰인) | F5: ='대기측정 분석결과서'!E6 -> 0 | M5: 사업장 종별 | P5: ='대기측정 분석결과서'!E10&" 종" -> 종 | W5: 맹호수 | Y5: 박민우 | AA5: 이동협 | AC5: 정우창 | AE5: 신민석 | AG5: 강민수 | AI5: 강원석 | AK5: 정종원 | AL5: 김흥록 | AM5: 송정현
B6: 환 경 기 술 인 | F6: ='대기측정 분석결과서'!E7 -> 여 형 석
A7: ③의뢰내용 | B7: 측 정 용 도 | F7: ="자가 측정용" -> 자가 측정용
B8: 굴 뚝 | F8: 굴뚝 명칭 | M8: 높이 [m] | O8: 안지름(측정공) [m] | S8: 굴뚝 종별 [종] | W8: 품책 | Y8: 대기기책 | AC8: 현재분책
F9: ='대기측정 분석결과서'!E9&" "&"(KGAR-"&RIGHT(YEAR('먼지측정 사전 Data'!N6),2)&"-"&'먼지측정 사전 Data'!O4&")" -> (KGAR-26-) | M9: ='한종_시료채취기록지 '!N3&" m" -> 0 m | O9: =IF(LEN('한종_시료채취기록지 '!F9)=1,'한종_시료채취기록지 '!F9&".000 m", IF(LEN('한종_시료채취기록지 '!F9)=3,'한종_시료채취기록지 '!F9&"00 m", IF(LEN('한종_시료채취기록지 '!F9)=4,'한종_시료채취기록지 '!F9&"0 m", '한종_시료채취기록지 '!F9&" m"))) -> 0.000 X 0.000 m | S9: ='대기측정 분석결과서'!E11&" 종" -> 종 | W9: 진수일 | Y9: 이나영 | AC9: 이나영 | AG9: 김태우 | AI9: 백희석 | AK9: 김인현
B10: 의 뢰 항 목 | F10: ='대기측정 분석결과서'!U11 -> THC (총 1 항목)
A11: ④시료채취 | B11: 현 장 기 상 | F11: 날씨 | H11: 기온 [℃] | J11: 습도 [%] | M11: 기압 [mmHg] | P11: 풍향 [풍] | S11: 풍속 [m/s]
F12: ='대기측정 분석결과서'!E17 -> 0 | H12: ='대기측정 분석결과서'!I17 -> 0 | J12: ='대기측정 분석결과서'!M17 -> 0 | M12: ='대기측정 분석결과서'!Q17 -> 0 | P12: ='대기측정 분석결과서'!V17 -> 0 | S12: ='대기측정 분석결과서'!AA17 -> 0 | W12: *분석기술인 -> 기술책임자
B13: 배 출 가 스 | F13: 표준산소농도 | I13: 실측산소농도 | M13: 배출가스유량(산소보정 전) | R13: 배출가스유량(산소보정 후)
F14: =IF('먼지측정 사전 Data'!R13=20.9,"-",'먼지측정 사전 Data'!R13&" %") -> - | I14: ='먼지측정 사전 Data'!H14&" %" -> 0 % | M14: ='시험일지(계산일지-2)'!R11&" S㎥/분" -> #DIV/0! | R14: ='시험일지(계산일지-2)'!Q21&" S㎥/분" -> #DIV/0!
F15: 수분량 | I15: 배출가스온도 | M15: 배출가스 유속 | R15: 기타
F16: ='먼지측정 사전 Data'!H59&" %" -> #DIV/0! | I16: ='먼지측정 사전 Data'!R69&" ℃" -> #DIV/0! | M16: ='먼지측정 사전 Data'!R82&" m/s" -> #DIV/0! | R16: -
B17: 방 지 시 설 | F17: 명 칭 | M17: 대 상 물 질 | R17: 방 지 효 율
F18: ='대기측정 분석결과서'!E13&IF('대기측정 분석결과서'!L10="",""," ("&'대기측정 분석결과서'!L10&")") | M18: - | R18: - | T18: %
B19: 채 취 일 시 | F19: 채취일 | H19: ='먼지측정 사전 Data'!N5 -> 0 | M19: 시료채취자 | Q19: ='대기측정 분석결과서'!U7&" (서명)" -> 0 (서명)
F20: 채취시간 | H20: ='먼지측정 사전 Data'!H6&" : "&IF('먼지측정 사전 Data'!I6<10,"0"&'먼지측정 사전 Data'!I6,'먼지측정 사전 Data'!I6)&" ~ "&'먼지측정 사전 Data'!K6&" : "&IF('먼지측정 사전 Data'!L6<10,"0"&'먼지측정 사전 Data'!L6,'먼지측정 사전 Data'!L6) -> : 0 ~ : 0 | Q20: ='대기측정 분석결과서'!X7&" (서명)" -> 0 (서명)
A21: ⑤ 시 설 가 동 상 황 | B21: 배출시설 명칭 | F21: 측정당시 시간당 사용(생산)량 | R21: 방지시설 명칭
F22: 연료사용량 | H22: 제품생산량 | J22: 소각량 | L22: 원료투입량 | N22: 종류 | P22: 단위
B23: ='대기측정 분석결과서'!E9 -> 0 | F23: ='대기측정 분석결과서'!L11 -> - | H23: - | J23: - | L23: - | N23: =IF(F23="-","-","LNG") -> - | P23: ='대기측정 분석결과서'!N11 -> Kg/Hr | R23: =IF(F18=0,"",'대기측정 분석결과서'!E13) -> 0
A24: ⑥측정분석결과 | B24: 측 정 항 목 | F24: 허용 기준 | I24: 측정분석값 | L24: 측정시간 | O24: 측정분석방법 (기기명) | S24: 비고
F26: =IF(B26="","","??") | H26: =IF(B26="","",INDEX('대기측정 분석결과서'!$AH$23:$AH$74,MATCH(B26,측정항목,0))) | I26: =IF(B26="","", IF(INDEX('대기측정 분석결과서'!$F$23:$I$74,MATCH(B26,항목,0),1)="","값없음", IF(ISERROR(FIXED(IF(INDEX('대기측정 분석결과서'!$F$23:$I$74,MATCH(B26,항목,0),1)<INDEX('대기측정 분석결과서'!$AG$23:$AG$74,MATCH(B26,항목,0)),"불검출", INDEX('대기측정 분석결과서'!$F$23:$I$74,MATCH(B26,항목,0),1)),INDEX('대기측정 분석결과서'!$AI$23:$AI$74,MATCH(B26,항목,0)))),"불검출", FIXED(INDEX('대기측정 분석결과서'!$F$23:$I$74,MATCH(B26,항목,0),1),INDEX('대기측정 분석결과서'!$AI$23:$AI$74,MATCH(B26,항목,0)))))) | L26: =IF(B26="","", IF(INDEX(Sheet1!$E$6:$F$51,MATCH(B26,Sheet1!$E$6:$E$51,0),2)="수은", '한종_시료채취기록지 '!$AG$20, IF(INDEX(Sheet1!$E$6:$F$51,MATCH(B26,Sheet1!$E$6:$E$51,0),2)="먼지", '한종_시료채취기록지 '!$Y$20, IF(INDEX(Sheet1!$E$6:$F$51,MATCH(B26,Sheet1!$E$6:$E$51,0),2)="THC", '한종_시료채취기록지 '!$AC$23, IF(INDEX(Sheet1!$E$6:$F$51,MATCH(B26,Sheet1!$E$6:$E$51,0),2)="매연", '한종_시료채취기록지 '!$AG$23, IF(INDEX(Sheet1!$E$6:$F$51,MATCH(B26,Sheet1!$E$6:$E$51,0),2)="옵티마", '한종_시료채취기록지 '!$Y$23, IF(INDEX(Sheet1!$E$6:$F$51,MATCH(B26,Sheet1!$E$6:$E$51,0),2)="중금속", '한종_시료채취기록지 '!$AC$20, IF(INDEX(Sheet1!$E$6:$F$51,MATCH(B26,Sheet1!$E$6:$E$51,0),2)="T", IFERROR( INDEX(가스상항목시간,MATCH("VOCs-T",가스상항목,0),5), INDEX(가스상항목시간,MATCH("VOCs-A",가스상항목,0),5) ), IF(INDEX(Sheet1!$E$6:$F$51,MATCH(B26,Sheet1!$E$6:$E$51,0),2)="A", INDEX(가스상항목시간,MATCH("VOCs-A",가스상항목,0),5), IF(INDEX(Sheet1!$E$6:$F$51,MATCH(B26,Sheet1!$E$6:$E$51,0),2)="DNPH", INDEX(가스상항목시간,MATCH("VOCs",가스상항목,0),5), INDEX(가스상항목시간,MATCH(B26,가스상항목,0),5) )))))))))) | O26: =IF(B26="","",INDEX('대기측정 분석결과서'!$Z$23:$Z$74,MATCH(B26,항목,0))) | S26: =IF(B26="","",INDEX('대기측정 분석결과서'!$M$23:$M$74,MATCH(B26,항목,0)))
F27: =IF(B27="","","??") | H27: =IF(B27="","",INDEX('대기측정 분석결과서'!$AH$23:$AH$74,MATCH(B27,측정항목,0))) | I27: =IF(B27="","", IF(INDEX('대기측정 분석결과서'!$F$23:$I$74,MATCH(B27,항목,0),1)="","값없음", IF(ISERROR(FIXED(IF(INDEX('대기측정 분석결과서'!$F$23:$I$74,MATCH(B27,항목,0),1)<INDEX('대기측정 분석결과서'!$AG$23:$AG$74,MATCH(B27,항목,0)),"불검출", INDEX('대기측정 분석결과서'!$F$23:$I$74,MATCH(B27,항목,0),1)),INDEX('대기측정 분석결과서'!$AI$23:$AI$74,MATCH(B27,항목,0)))),"불검출", FIXED(INDEX('대기측정 분석결과서'!$F$23:$I$74,MATCH(B27,항목,0),1),INDEX('대기측정 분석결과서'!$AI$23:$AI$74,MATCH(B27,항목,0)))))) | L27: =IF(B27="","", IF(INDEX(Sheet1!$E$6:$F$51,MATCH(B27,Sheet1!$E$6:$E$51,0),2)="수은", '한종_시료채취기록지 '!$AG$20, IF(INDEX(Sheet1!$E$6:$F$51,MATCH(B27,Sheet1!$E$6:$E$51,0),2)="먼지", '한종_시료채취기록지 '!$Y$20, IF(INDEX(Sheet1!$E$6:$F$51,MATCH(B27,Sheet1!$E$6:$E$51,0),2)="THC", '한종_시료채취기록지 '!$AC$23, IF(INDEX(Sheet1!$E$6:$F$51,MATCH(B27,Sheet1!$E$6:$E$51,0),2)="매연", '한종_시료채취기록지 '!$AG$23, IF(INDEX(Sheet1!$E$6:$F$51,MATCH(B27,Sheet1!$E$6:$E$51,0),2)="옵티마", '한종_시료채취기록지 '!$Y$23, IF(INDEX(Sheet1!$E$6:$F$51,MATCH(B27,Sheet1!$E$6:$E$51,0),2)="중금속", '한종_시료채취기록지 '!$AC$20, IF(INDEX(Sheet1!$E$6:$F$51,MATCH(B27,Sheet1!$E$6:$E$51,0),2)="T", IFERROR( INDEX(가스상항목시간,MATCH("VOCs-T",가스상항목,0),5), INDEX(가스상항목시간,MATCH("VOCs-A",가스상항목,0),5) ), IF(INDEX(Sheet1!$E$6:$F$51,MATCH(B27,Sheet1!$E$6:$E$51,0),2)="A", INDEX(가스상항목시간,MATCH("VOCs-A",가스상항목,0),5), IF(INDEX(Sheet1!$E$6:$F$51,MATCH(B27,Sheet1!$E$6:$E$51,0),2)="DNPH", INDEX(가스상항목시간,MATCH("VOCs",가스상항목,0),5), INDEX(가스상항목시간,MATCH(B27,가스상항목,0),5) )))))))))) | O27: =IF(B27="","",INDEX('대기측정 분석결과서'!$Z$23:$Z$74,MATCH(B27,항목,0))) | S27: =IF(B27="","",INDEX('대기측정 분석결과서'!$M$23:$M$74,MATCH(B27,항목,0))) | W27: -이하여백-
F28: =IF(B28="","","??") | H28: =IF(B28="","",INDEX('대기측정 분석결과서'!$AH$23:$AH$74,MATCH(B28,측정항목,0))) | I28: =IF(B28="","", IF(INDEX('대기측정 분석결과서'!$F$23:$I$74,MATCH(B28,항목,0),1)="","값없음", IF(ISERROR(FIXED(IF(INDEX('대기측정 분석결과서'!$F$23:$I$74,MATCH(B28,항목,0),1)<INDEX('대기측정 분석결과서'!$AG$23:$AG$74,MATCH(B28,항목,0)),"불검출", INDEX('대기측정 분석결과서'!$F$23:$I$74,MATCH(B28,항목,0),1)),INDEX('대기측정 분석결과서'!$AI$23:$AI$74,MATCH(B28,항목,0)))),"불검출", FIXED(INDEX('대기측정 분석결과서'!$F$23:$I$74,MATCH(B28,항목,0),1),INDEX('대기측정 분석결과서'!$AI$23:$AI$74,MATCH(B28,항목,0)))))) | L28: =IF(B28="","", IF(INDEX(Sheet1!$E$6:$F$51,MATCH(B28,Sheet1!$E$6:$E$51,0),2)="수은", '한종_시료채취기록지 '!$AG$20, IF(INDEX(Sheet1!$E$6:$F$51,MATCH(B28,Sheet1!$E$6:$E$51,0),2)="먼지", '한종_시료채취기록지 '!$Y$20, IF(INDEX(Sheet1!$E$6:$F$51,MATCH(B28,Sheet1!$E$6:$E$51,0),2)="THC", '한종_시료채취기록지 '!$AC$23, IF(INDEX(Sheet1!$E$6:$F$51,MATCH(B28,Sheet1!$E$6:$E$51,0),2)="매연", '한종_시료채취기록지 '!$AG$23, IF(INDEX(Sheet1!$E$6:$F$51,MATCH(B28,Sheet1!$E$6:$E$51,0),2)="옵티마", '한종_시료채취기록지 '!$Y$23, IF(INDEX(Sheet1!$E$6:$F$51,MATCH(B28,Sheet1!$E$6:$E$51,0),2)="중금속", '한종_시료채취기록지 '!$AC$20, IF(INDEX(Sheet1!$E$6:$F$51,MATCH(B28,Sheet1!$E$6:$E$51,0),2)="T", IFERROR( INDEX(가스상항목시간,MATCH("VOCs-T",가스상항목,0),5), INDEX(가스상항목시간,MATCH("VOCs-A",가스상항목,0),5) ), IF(INDEX(Sheet1!$E$6:$F$51,MATCH(B28,Sheet1!$E$6:$E$51,0),2)="A", INDEX(가스상항목시간,MATCH("VOCs-A",가스상항목,0),5), IF(INDEX(Sheet1!$E$6:$F$51,MATCH(B28,Sheet1!$E$6:$E$51,0),2)="DNPH", INDEX(가스상항목시간,MATCH("VOCs",가스상항목,0),5), INDEX(가스상항목시간,MATCH(B28,가스상항목,0),5) )))))))))) | O28: =IF(B28="","",INDEX('대기측정 분석결과서'!$Z$23:$Z$74,MATCH(B28,항목,0))) | S28: =IF(B28="","",INDEX('대기측정 분석결과서'!$M$23:$M$74,MATCH(B28,항목,0)))
F29: =IF(B29="","","??") | H29: =IF(B29="","",INDEX('대기측정 분석결과서'!$AH$23:$AH$74,MATCH(B29,측정항목,0))) | I29: =IF(B29="","", IF(INDEX('대기측정 분석결과서'!$F$23:$I$74,MATCH(B29,항목,0),1)="","값없음", IF(ISERROR(FIXED(IF(INDEX('대기측정 분석결과서'!$F$23:$I$74,MATCH(B29,항목,0),1)<INDEX('대기측정 분석결과서'!$AG$23:$AG$74,MATCH(B29,항목,0)),"불검출", INDEX('대기측정 분석결과서'!$F$23:$I$74,MATCH(B29,항목,0),1)),INDEX('대기측정 분석결과서'!$AI$23:$AI$74,MATCH(B29,항목,0)))),"불검출", FIXED(INDEX('대기측정 분석결과서'!$F$23:$I$74,MATCH(B29,항목,0),1),INDEX('대기측정 분석결과서'!$AI$23:$AI$74,MATCH(B29,항목,0)))))) | L29: =IF(B29="","", IF(INDEX(Sheet1!$E$6:$F$51,MATCH(B29,Sheet1!$E$6:$E$51,0),2)="수은", '한종_시료채취기록지 '!$AG$20, IF(INDEX(Sheet1!$E$6:$F$51,MATCH(B29,Sheet1!$E$6:$E$51,0),2)="먼지", '한종_시료채취기록지 '!$Y$20, IF(INDEX(Sheet1!$E$6:$F$51,MATCH(B29,Sheet1!$E$6:$E$51,0),2)="THC", '한종_시료채취기록지 '!$AC$23, IF(INDEX(Sheet1!$E$6:$F$51,MATCH(B29,Sheet1!$E$6:$E$51,0),2)="매연", '한종_시료채취기록지 '!$AG$23, IF(INDEX(Sheet1!$E$6:$F$51,MATCH(B29,Sheet1!$E$6:$E$51,0),2)="옵티마", '한종_시료채취기록지 '!$Y$23, IF(INDEX(Sheet1!$E$6:$F$51,MATCH(B29,Sheet1!$E$6:$E$51,0),2)="중금속", '한종_시료채취기록지 '!$AC$20, IF(INDEX(Sheet1!$E$6:$F$51,MATCH(B29,Sheet1!$E$6:$E$51,0),2)="T", IFERROR( INDEX(가스상항목시간,MATCH("VOCs-T",가스상항목,0),5), INDEX(가스상항목시간,MATCH("VOCs-A",가스상항목,0),5) ), IF(INDEX(Sheet1!$E$6:$F$51,MATCH(B29,Sheet1!$E$6:$E$51,0),2)="A", INDEX(가스상항목시간,MATCH("VOCs-A",가스상항목,0),5), IF(INDEX(Sheet1!$E$6:$F$51,MATCH(B29,Sheet1!$E$6:$E$51,0),2)="DNPH", INDEX(가스상항목시간,MATCH("VOCs",가스상항목,0),5), INDEX(가스상항목시간,MATCH(B29,가스상항목,0),5) )))))))))) | O29: =IF(B29="","",INDEX('대기측정 분석결과서'!$Z$23:$Z$74,MATCH(B29,항목,0))) | S29: =IF(B29="","",INDEX('대기측정 분석결과서'!$M$23:$M$74,MATCH(B29,항목,0)))
F30: =IF(B30="","","??") | H30: =IF(B30="","",INDEX('대기측정 분석결과서'!$AH$23:$AH$74,MATCH(B30,측정항목,0))) | I30: =IF(B30="","", IF(INDEX('대기측정 분석결과서'!$F$23:$I$74,MATCH(B30,항목,0),1)="","값없음", IF(ISERROR(FIXED(IF(INDEX('대기측정 분석결과서'!$F$23:$I$74,MATCH(B30,항목,0),1)<INDEX('대기측정 분석결과서'!$AG$23:$AG$74,MATCH(B30,항목,0)),"불검출", INDEX('대기측정 분석결과서'!$F$23:$I$74,MATCH(B30,항목,0),1)),INDEX('대기측정 분석결과서'!$AI$23:$AI$74,MATCH(B30,항목,0)))),"불검출", FIXED(INDEX('대기측정 분석결과서'!$F$23:$I$74,MATCH(B30,항목,0),1),INDEX('대기측정 분석결과서'!$AI$23:$AI$74,MATCH(B30,항목,0)))))) | L30: =IF(B30="","", IF(INDEX(Sheet1!$E$6:$F$51,MATCH(B30,Sheet1!$E$6:$E$51,0),2)="수은", '한종_시료채취기록지 '!$AG$20, IF(INDEX(Sheet1!$E$6:$F$51,MATCH(B30,Sheet1!$E$6:$E$51,0),2)="먼지", '한종_시료채취기록지 '!$Y$20, IF(INDEX(Sheet1!$E$6:$F$51,MATCH(B30,Sheet1!$E$6:$E$51,0),2)="THC", '한종_시료채취기록지 '!$AC$23, IF(INDEX(Sheet1!$E$6:$F$51,MATCH(B30,Sheet1!$E$6:$E$51,0),2)="매연", '한종_시료채취기록지 '!$AG$23, IF(INDEX(Sheet1!$E$6:$F$51,MATCH(B30,Sheet1!$E$6:$E$51,0),2)="옵티마", '한종_시료채취기록지 '!$Y$23, IF(INDEX(Sheet1!$E$6:$F$51,MATCH(B30,Sheet1!$E$6:$E$51,0),2)="중금속", '한종_시료채취기록지 '!$AC$20, IF(INDEX(Sheet1!$E$6:$F$51,MATCH(B30,Sheet1!$E$6:$E$51,0),2)="T", IFERROR( INDEX(가스상항목시간,MATCH("VOCs-T",가스상항목,0),5), INDEX(가스상항목시간,MATCH("VOCs-A",가스상항목,0),5) ), IF(INDEX(Sheet1!$E$6:$F$51,MATCH(B30,Sheet1!$E$6:$E$51,0),2)="A", INDEX(가스상항목시간,MATCH("VOCs-A",가스상항목,0),5), IF(INDEX(Sheet1!$E$6:$F$51,MATCH(B30,Sheet1!$E$6:$E$51,0),2)="DNPH", INDEX(가스상항목시간,MATCH("VOCs",가스상항목,0),5), INDEX(가스상항목시간,MATCH(B30,가스상항목,0),5) )))))))))) | O30: =IF(B30="","",INDEX('대기측정 분석결과서'!$Z$23:$Z$74,MATCH(B30,항목,0))) | S30: =IF(B30="","",INDEX('대기측정 분석결과서'!$M$23:$M$74,MATCH(B30,항목,0)))
F31: =IF(B31="","","??") | H31: =IF(B31="","",INDEX('대기측정 분석결과서'!$AH$23:$AH$74,MATCH(B31,측정항목,0))) | I31: =IF(B31="","", IF(INDEX('대기측정 분석결과서'!$F$23:$I$74,MATCH(B31,항목,0),1)="","값없음", IF(ISERROR(FIXED(IF(INDEX('대기측정 분석결과서'!$F$23:$I$74,MATCH(B31,항목,0),1)<INDEX('대기측정 분석결과서'!$AG$23:$AG$74,MATCH(B31,항목,0)),"불검출", INDEX('대기측정 분석결과서'!$F$23:$I$74,MATCH(B31,항목,0),1)),INDEX('대기측정 분석결과서'!$AI$23:$AI$74,MATCH(B31,항목,0)))),"불검출", FIXED(INDEX('대기측정 분석결과서'!$F$23:$I$74,MATCH(B31,항목,0),1),INDEX('대기측정 분석결과서'!$AI$23:$AI$74,MATCH(B31,항목,0)))))) | L31: =IF(B31="","", IF(INDEX(Sheet1!$E$6:$F$51,MATCH(B31,Sheet1!$E$6:$E$51,0),2)="수은", '한종_시료채취기록지 '!$AG$20, IF(INDEX(Sheet1!$E$6:$F$51,MATCH(B31,Sheet1!$E$6:$E$51,0),2)="먼지", '한종_시료채취기록지 '!$Y$20, IF(INDEX(Sheet1!$E$6:$F$51,MATCH(B31,Sheet1!$E$6:$E$51,0),2)="THC", '한종_시료채취기록지 '!$AC$23, IF(INDEX(Sheet1!$E$6:$F$51,MATCH(B31,Sheet1!$E$6:$E$51,0),2)="매연", '한종_시료채취기록지 '!$AG$23, IF(INDEX(Sheet1!$E$6:$F$51,MATCH(B31,Sheet1!$E$6:$E$51,0),2)="옵티마", '한종_시료채취기록지 '!$Y$23, IF(INDEX(Sheet1!$E$6:$F$51,MATCH(B31,Sheet1!$E$6:$E$51,0),2)="중금속", '한종_시료채취기록지 '!$AC$20, IF(INDEX(Sheet1!$E$6:$F$51,MATCH(B31,Sheet1!$E$6:$E$51,0),2)="T", IFERROR( INDEX(가스상항목시간,MATCH("VOCs-T",가스상항목,0),5), INDEX(가스상항목시간,MATCH("VOCs-A",가스상항목,0),5) ), IF(INDEX(Sheet1!$E$6:$F$51,MATCH(B31,Sheet1!$E$6:$E$51,0),2)="A", INDEX(가스상항목시간,MATCH("VOCs-A",가스상항목,0),5), IF(INDEX(Sheet1!$E$6:$F$51,MATCH(B31,Sheet1!$E$6:$E$51,0),2)="DNPH", INDEX(가스상항목시간,MATCH("VOCs",가스상항목,0),5), INDEX(가스상항목시간,MATCH(B31,가스상항목,0),5) )))))))))) | O31: =IF(B31="","",INDEX('대기측정 분석결과서'!$Z$23:$Z$74,MATCH(B31,항목,0))) | S31: =IF(B31="","",INDEX('대기측정 분석결과서'!$M$23:$M$74,MATCH(B31,항목,0)))
F32: =IF(B32="","","??") | H32: =IF(B32="","",INDEX('대기측정 분석결과서'!$AH$23:$AH$74,MATCH(B32,측정항목,0))) | I32: =IF(B32="","", IF(INDEX('대기측정 분석결과서'!$F$23:$I$74,MATCH(B32,항목,0),1)="","값없음", IF(ISERROR(FIXED(IF(INDEX('대기측정 분석결과서'!$F$23:$I$74,MATCH(B32,항목,0),1)<INDEX('대기측정 분석결과서'!$AG$23:$AG$74,MATCH(B32,항목,0)),"불검출", INDEX('대기측정 분석결과서'!$F$23:$I$74,MATCH(B32,항목,0),1)),INDEX('대기측정 분석결과서'!$AI$23:$AI$74,MATCH(B32,항목,0)))),"불검출", FIXED(INDEX('대기측정 분석결과서'!$F$23:$I$74,MATCH(B32,항목,0),1),INDEX('대기측정 분석결과서'!$AI$23:$AI$74,MATCH(B32,항목,0)))))) | L32: =IF(B32="","", IF(INDEX(Sheet1!$E$6:$F$51,MATCH(B32,Sheet1!$E$6:$E$51,0),2)="수은", '한종_시료채취기록지 '!$AG$20, IF(INDEX(Sheet1!$E$6:$F$51,MATCH(B32,Sheet1!$E$6:$E$51,0),2)="먼지", '한종_시료채취기록지 '!$Y$20, IF(INDEX(Sheet1!$E$6:$F$51,MATCH(B32,Sheet1!$E$6:$E$51,0),2)="THC", '한종_시료채취기록지 '!$AC$23, IF(INDEX(Sheet1!$E$6:$F$51,MATCH(B32,Sheet1!$E$6:$E$51,0),2)="매연", '한종_시료채취기록지 '!$AG$23, IF(INDEX(Sheet1!$E$6:$F$51,MATCH(B32,Sheet1!$E$6:$E$51,0),2)="옵티마", '한종_시료채취기록지 '!$Y$23, IF(INDEX(Sheet1!$E$6:$F$51,MATCH(B32,Sheet1!$E$6:$E$51,0),2)="중금속", '한종_시료채취기록지 '!$AC$20, IF(INDEX(Sheet1!$E$6:$F$51,MATCH(B32,Sheet1!$E$6:$E$51,0),2)="T", IFERROR( INDEX(가스상항목시간,MATCH("VOCs-T",가스상항목,0),5), INDEX(가스상항목시간,MATCH("VOCs-A",가스상항목,0),5) ), IF(INDEX(Sheet1!$E$6:$F$51,MATCH(B32,Sheet1!$E$6:$E$51,0),2)="A", INDEX(가스상항목시간,MATCH("VOCs-A",가스상항목,0),5), IF(INDEX(Sheet1!$E$6:$F$51,MATCH(B32,Sheet1!$E$6:$E$51,0),2)="DNPH", INDEX(가스상항목시간,MATCH("VOCs",가스상항목,0),5), INDEX(가스상항목시간,MATCH(B32,가스상항목,0),5) )))))))))) | O32: =IF(B32="","",INDEX('대기측정 분석결과서'!$Z$23:$Z$74,MATCH(B32,항목,0))) | S32: =IF(B32="","",INDEX('대기측정 분석결과서'!$M$23:$M$74,MATCH(B32,항목,0)))
F33: =IF(B33="","","??") | H33: =IF(B33="","",INDEX('대기측정 분석결과서'!$AH$23:$AH$74,MATCH(B33,측정항목,0))) | I33: =IF(B33="","", IF(INDEX('대기측정 분석결과서'!$F$23:$I$74,MATCH(B33,항목,0),1)="","값없음", IF(ISERROR(FIXED(IF(INDEX('대기측정 분석결과서'!$F$23:$I$74,MATCH(B33,항목,0),1)<INDEX('대기측정 분석결과서'!$AG$23:$AG$74,MATCH(B33,항목,0)),"불검출", INDEX('대기측정 분석결과서'!$F$23:$I$74,MATCH(B33,항목,0),1)),INDEX('대기측정 분석결과서'!$AI$23:$AI$74,MATCH(B33,항목,0)))),"불검출", FIXED(INDEX('대기측정 분석결과서'!$F$23:$I$74,MATCH(B33,항목,0),1),INDEX('대기측정 분석결과서'!$AI$23:$AI$74,MATCH(B33,항목,0)))))) | L33: =IF(B33="","", IF(INDEX(Sheet1!$E$6:$F$51,MATCH(B33,Sheet1!$E$6:$E$51,0),2)="수은", '한종_시료채취기록지 '!$AG$20, IF(INDEX(Sheet1!$E$6:$F$51,MATCH(B33,Sheet1!$E$6:$E$51,0),2)="먼지", '한종_시료채취기록지 '!$Y$20, IF(INDEX(Sheet1!$E$6:$F$51,MATCH(B33,Sheet1!$E$6:$E$51,0),2)="THC", '한종_시료채취기록지 '!$AC$23, IF(INDEX(Sheet1!$E$6:$F$51,MATCH(B33,Sheet1!$E$6:$E$51,0),2)="매연", '한종_시료채취기록지 '!$AG$23, IF(INDEX(Sheet1!$E$6:$F$51,MATCH(B33,Sheet1!$E$6:$E$51,0),2)="옵티마", '한종_시료채취기록지 '!$Y$23, IF(INDEX(Sheet1!$E$6:$F$51,MATCH(B33,Sheet1!$E$6:$E$51,0),2)="중금속", '한종_시료채취기록지 '!$AC$20, IF(INDEX(Sheet1!$E$6:$F$51,MATCH(B33,Sheet1!$E$6:$E$51,0),2)="T", IFERROR( INDEX(가스상항목시간,MATCH("VOCs-T",가스상항목,0),5), INDEX(가스상항목시간,MATCH("VOCs-A",가스상항목,0),5) ), IF(INDEX(Sheet1!$E$6:$F$51,MATCH(B33,Sheet1!$E$6:$E$51,0),2)="A", INDEX(가스상항목시간,MATCH("VOCs-A",가스상항목,0),5), IF(INDEX(Sheet1!$E$6:$F$51,MATCH(B33,Sheet1!$E$6:$E$51,0),2)="DNPH", INDEX(가스상항목시간,MATCH("VOCs",가스상항목,0),5), INDEX(가스상항목시간,MATCH(B33,가스상항목,0),5) )))))))))) | O33: =IF(B33="","",INDEX('대기측정 분석결과서'!$Z$23:$Z$74,MATCH(B33,항목,0))) | S33: =IF(B33="","",INDEX('대기측정 분석결과서'!$M$23:$M$74,MATCH(B33,항목,0)))
